Workbook
Name l: #REF!
Name start_day: #REF!
Name 宿命: #REF!
Name 宿命2: #REF!

Sheet リバース占い鑑定結果
A1: リバース星座占い鑑定結果
A2: 生年月日 | B2: 年 | C2: 月 | D2: 日
B3: =リバース占い!I3 -> 1981 | C3: =リバース占い!K3 -> 9 | D3: =リバース占い!L3 -> 7
A5: 表星座 | B5: 私たちが普段意識している星座（太陽星座）は社会的な表の顔を示します。 | P5: イベント | Q5: 意味 | S5: 干合名 | T5: 化名 | U5: キャラ変
A6: =リバース占い!V43 -> おとめ座 | L6: 害 | M6: ストレス | N6: 病気注意 | P6: ストレス | Q6: 病気注意 | S6: 甲己干合 | T6: 土化 | U6: オカン化
A7: 全体運 | B7: =VLOOKUP($A$6, 表裏星座一覧!A:F, 2, FALSE) -> 完璧を求める鋭い分析力と、他者のために献身的に尽くす卓越した実務能力に秀でています。ルーペで物事を見るように細部まで目が行き届き、誰も気づかないような小さなミスや改善点を瞬時に見抜く才能があります。秩序と清潔を愛し、カオスな状況を美しく整理整頓していくことに喜びを感じます。自分にも他人にも厳しい傾向があるため、時には「まぁいいか」と許す大らかさを持つことで生きやすくなります。 | L7: 害刑 | M7: ストレス・バトル | N7: ストレスと揉め事 | P7: ストレス・バトル | Q7: ストレスと揉め事 | S7: 乙庚干合 | T7: 金化 | U7: クール化
A8: 仕事運 | B8: =VLOOKUP($A$6, 表裏星座一覧!A:F, 3, FALSE) -> 医療、データ分析、秘書、経理、プログラミングなど、正確性と緻密なスケジュール管理が求められる分野で右に出る者はいません。組織の中でトップに立つよりも、優秀なナンバーツーや参謀役として、リーダーの弱点を完璧にフォローするポジションで絶対的な評価を得ます。あなたの整然とした仕事ぶりと有能さは、どんな職場でも「絶対に手放せない人材」として重宝されます。 | L8: 刑 | M8: バトル | N8: 人間関係のトラブル | P8: バトル | Q8: 人間関係のトラブル | S8: 丙辛干合 | T8: 水化 | U8: デレ化
A9: 恋愛結婚運 | B9: =VLOOKUP($A$6, 表裏星座一覧!A:F, 4, FALSE) -> 純粋で潔癖なロマンチストであり、恋愛に対しても「完璧さ」を求めるため、非常に理想が高く、相手選びに慎重です。情熱だけで突っ走ることはなく、相手の生活態度や経済観念をしっかりと観察します。一度交際が始まると、相手の世話を焼き、献身的に尽くすことに深い愛情を感じます。結婚後は家計の管理や家事を完璧にこなし、清潔で規則正しい、非常に安定した模範的な家庭を築きます。 | L9: 刑破 | M9: バトル・フリーズ | N9: 揉め事と物事の停滞 | P9: バトル・フリーズ | Q9: 揉め事と物事の停滞 | S9: 丁壬干合 | T9: 木化 | U9: エロ化
A10: 金運 | B10: =VLOOKUP($A$6, 表裏星座一覧!A:F, 5, FALSE) -> 無駄な支出を極端に嫌い、1円単位までしっかりと家計を管理できる非常に優秀で堅実な金運の持ち主です。衝動買いはほとんどせず、コストパフォーマンスや実用性を徹底的にリサーチしてから買い物をします。リスクの高いギャンブルや投資には手を出さず、安全確実な預貯金や定額積立などで、気づけば大きな財産を形成しているという手堅さが最大の強みです。 | L10: 支合 | M10: バランス | N10: 結びつきやまとまり | P10: バランス | Q10: 結びつきやまとまり | S10: 戊癸干合 | T10: 火化 | U10: オトメ化
A11: 健康運 | B11: =VLOOKUP($A$6, 表裏星座一覧!A:F, 6, FALSE) -> 大腸や小腸などの消化器官が弱点で、精神的なストレスや心配事がダイレクトにお腹の調子に影響します。完璧主義ゆえに神経をすり減らしやすいため、規則正しい生活リズムと、無農薬野菜やオーガニック食品など身体に優しい食事を摂ることが健康の基本です。休日は部屋の掃除や整理整頓をすることで心がスッキリと浄化され、自律神経のバランスを取り戻すことができます。 | L11: 合刑 | M11: バランス・バトル | N11: まとまる中の揉め事 | P11: バランス・バトル | Q11: まとまる中の揉め事
L12: 合破 | M12: バランス・フリーズ | N12: まとまる中の停滞 | P12: バランス・フリーズ | Q12: まとまる中の停滞
A13: 裏星座 | B13: 東洋の宿命理論（算命学）を掛け合わせることで浮き彫りになるあなたの無意識の裏の顔 | L13: 冲刑 | M13: クラッシュ・バトル | N13: 衝突と対人トラブル | P13: クラッシュ・バトル | Q13: 衝突と対人トラブル
A14: =リバース占い!V42 -> 裏かに座 | L14: 冲破 | M14: クラッシュ・フリーズ | N14: 衝突と物事の停滞 | P14: クラッシュ・フリーズ | Q14: 衝突と物事の停滞
A15: 全体運 | B15: =VLOOKUP($A$14, 表裏星座一覧!A:F, 2, FALSE) -> 他人に決して無断で踏み込まれない、強固で神聖な「聖域」を心の奥底に持つ孤高の存在です。表面上は穏やかで周囲に合わせているように見えても、内面にはいかなる逆境にも屈しない底知れぬ忍耐力と、世間の理不尽に対する強い反骨精神を秘めています。自分のテリトリーや愛する人々を脅かすものに対しては、徹底的に戦い抜く防衛本能の強さを持っています。容易には人に本性を見せず、真の理解者を得るまでには時間がかかりますが、自らの聖域の中でじっくりと魂を磨き上げ、最終的には誰にも到達できないような深い精神性と実力を身につける大器晩成型の重厚な人生を歩みます。 | L15: 対冲 | M15: クラッシュ | N15: 真正面からの衝突 | P15: クラッシュ | Q15: 真正面からの衝突
A16: 仕事運 | B16: =VLOOKUP($A$14, 表裏星座一覧!A:F, 3, FALSE) -> 他人のペースや職場のノイズに巻き込まれることを嫌い、自分のペースで深く没頭できる専門分野や職人肌の仕事において、他の追随を許さない絶大な信頼を得ます。底知れぬ忍耐力と反骨精神を活かし、人が投げ出すような困難な課題や、緻密な集中力が求められる業務に黙々と取り組み、完璧な結果を出して見せます。表立って目立つポジションよりも、「この人に任せておけば絶対に間違いない」と言われるような、組織の裏大黒柱や専門家としての地位を確立することで、生涯にわたって揺るぎないキャリアと名誉を築き上げる仕事運です。 | L16: 対冲刑 | M16: メガクラッシュ | N16: 激しい衝突と争い | P16: メガクラッシュ | Q16: 激しい衝突と争い
A17: 恋愛結婚運 | B17: =VLOOKUP($A$14, 表裏星座一覧!A:F, 4, FALSE) -> 警戒心が強く、自らの聖域を守ろうとするため、他者に心を開くのには非常に長い時間を必要とします。しかし、厳しい審査を経て一度この人と決めて愛せば、見返りを一切求めない底知れぬ深い愛情を永遠に注ぎ続けるという、究極の愛情深さを持っています。恋愛の延長線上には常に「家族」や「絶対的な味方」としての絆を求めており、遊びの恋には見向きもしません。結婚後はパートナーや子供を自分の神聖なテリトリー内に迎え入れ、どんな自己犠牲を払ってでも家族を守り抜く、非常に強固で温かい愛情に満ちた家庭を築き上げます。 | L17: 大半会 | M17: フィーバー | N17: 異分野融合と大発展 | P17: フィーバー | Q17: 異分野融合と大発展
A18: 金運 | B18: =VLOOKUP($A$14, 表裏星座一覧!A:F, 5, FALSE) -> 他人に踏み込まれない聖域を持つ孤高の性質は、金銭感覚においても非常に保守的で防衛本能の強い形となって表れます。ギャンブルや不確実な投資には一切手を出さず、自分のペースで没頭できる専門分野で確実に稼いだお金を、将来の安心のためにコツコツと蓄積していく能力に並外れたものがあります。底知れぬ忍耐力を持って無駄遣いを徹底的に排除し、家族や自分の城（マイホームなど）を守るための強固な経済的基盤を長年かけて築き上げます。決して派手さはありませんが、晩年になるほど圧倒的な安心感を手にする手堅い金運です。 | L18: 同 | M18: ブースト | N18: 要素の強調や倍増 | P18: ブースト | Q18: 要素の強調や倍増
A19: 健康運 | B19: =VLOOKUP($A$14, 表裏星座一覧!A:F, 6, FALSE) -> 底知れぬ忍耐力を持つがゆえに、ストレスや疲労を限界の限界まで一人で耐え忍んでしまう傾向があり、それが健康面での最大の懸念事項です。他人に踏み込まれない聖域を侵されたり、人間関係で強いストレスを感じると、胃腸などの消化器官にダイレクトに不調が現れやすい体質を持っています。健康を維持するためには、絶対に誰にも邪魔されない自分だけのリラックス空間（自室や趣味の場所）を整え、そこに引きこもって感情を完全にリセットする時間を定期的に確保することが、心身のバランスを保つための最重要課題となります。 | L19: 納音 | M19: ブレーキ | N19: 白紙に戻る・停止 | P19: ブレーキ | Q19: 白紙に戻る・停止
L20: 律音 | M20: リスタート | N20: 再出発や新たな開始 | P20: リスタート | Q20: 再出発や新たな開始
A21: リバーシブル・アングル6分類：表と裏のワタシの交差点 | L21: 半会 | M21: シナジー | N21: 新たな広がりや発展 | P21: シナジー | Q21: 新たな広がりや発展
A22: あなたが社会で見せるオモテの顔（表星座）と、心の奥底に隠されたガチの素顔（裏星座）。この2つが12星座の円盤上で「どのくらいの角度（距離）」にあるかによって、あなたの心の中で起きる化学反応は6つの角度タイプ（①0°②30°③60°,120°④90°⑤150°⑥180°）に分類されます。 | L22: 準合 | M22: スタンバイ | N22: 発展や変化の準備 | P22: スタンバイ | Q22: 発展や変化の準備
A23: アングル （角度・アスペクト） | B23: =リバース占い!W43 -> 60°・120°（セクスタイル・トライン） | F23: =リバース占い!X43 -> 【ナチュラル・ハーモニー型】 | L23: 破 | M23: フリーズ | N23: 物事の停滞や破損 | P23: フリーズ | Q23: 物事の停滞や破損
A24: アングルの内容説明 | C24: =VLOOKUP($B$23, 表裏星座一覧!A:F, 3, FALSE) -> 表と裏が同じ、または相性の良い価値観（エレメント）で結ばれた調和の配置です。 | L24: 準方位 | M24: スクラム | N24: 強固な結びつき | P24: スクラム | Q24: 強固な結びつき
A25: 全体の特性 | C25: =VLOOKUP($B$23, 表裏星座一覧!A:F, 4, FALSE) -> 社会的な「表の顔」と深層の「裏の顔」が、お互いに協力し合い、自然にエネルギーを循環させる最もストレスの少ない配置です。アウターキャラのスキルを使って、インナーキャラの欲求をスムーズに満たすことができるため、人生において「無理をしている」という感覚が非常に薄いのが特徴です。生まれながらにして物事の要領を掴むのが上手く、周囲からは「天才肌」「いつも自然体で恵まれている人」として愛されます。人間関係の構築や才能の発揮において、摩擦ゼロで波に乗ることができる天性の才能と幸運の持ち主です。 | L25: 天剋地冲 | M25: ビックバン | N25: 強制的なリセット | P25: ビックバン | Q25: 強制的なリセット
A26: 葛藤パターン | C26: =VLOOKUP($B$23, 表裏星座一覧!A:F, 5, FALSE) -> 物事が比較的スムーズに運びやすいため、極限状態での「泥臭いハングリー精神」や「何がなんでも這い上がる執念」が育ちにくいのが最大の弱点です。想定外の巨大な壁や、理不尽な逆境に直面した時、戦う前に「まあ、別の楽な道に行けばいいか」と簡単に見切りをつけてしまう傾向があります。自分の中での摩擦や葛藤がない分、現状維持の「ぬるま湯（コンフォートゾーン）」に浸かりやすく、本来持っている莫大なポテンシャルの半分も発揮せずに人生を終えてしまうという、もったいないパターンの陥りやすさを持っています。 | L26: 自刑 | M26: セルフバトル | N26: 身内や自身との葛藤 | P26: セルフバトル | Q26: 身内や自身との葛藤
A27: 開運パターン | C27: =VLOOKUP($B$23, 表裏星座一覧!A:F, 6, FALSE) -> あなたに必要なのは、意図的に「コンフォートゾーン（安全地帯）から抜け出す」という意識です。生まれ持った才能と運の流れがすでに完璧に整っているため、あえて少しハードルの高い目標を設定し、汗をかいて努力した時の成功率は144パターンの中でトップクラスです。自分を甘やかさないために、少し厳しめの指導者や、あなたとは全く違う価値観で刺激を与えてくれるライバルを意図的に持ちましょう。恵まれた環境に甘んじず、自ら「挑戦の負荷」をかけることで、あなたの運命は一気にスケールアップします。 | L27: － | M27: － | N27: －
A30: 年天運 | N30: 家庭 | O30: 自分 | P30: 社会 | Q30: 家庭 | R30: 自分 | S30: 社会 | T30: 家庭 | U30: 自分 | V30: 社会
A31: =YEAR(TODAY())-3 -> 2023 | B31: =INDEX(リバース占い!AV:AV, MATCH(A31, INDEX(VALUE(TRIM(リバース占い!AG:AG)), 0), 0)) -> 有頂天 | C31: =INDEX(リバース占い!AW:AW, MATCH(A31, INDEX(VALUE(TRIM(リバース占い!AG:AG)), 0), 0)) -> 第2の絶頂期。過去の縁が繋がり、周囲を巻き込み大きな成果を出す。 | K31: =INDEX(リバース占い!AN:AN, MATCH($A31, INDEX(VALUE(TRIM(リバース占い!$AG:$AG)), 0), 0)) -> 刑 | L31: =INDEX(リバース占い!AO:AO, MATCH($A31, INDEX(VALUE(TRIM(リバース占い!$AG:$AG)), 0), 0)) -> － | M31: =INDEX(リバース占い!AP:AP, MATCH($A31, INDEX(VALUE(TRIM(リバース占い!$AG:$AG)), 0), 0)) -> 対冲 | N31: =VLOOKUP(K31,$L$6:$P$27,2,FALSE) -> バトル | O31: =VLOOKUP(L31,$L$6:$P$27,2,FALSE) -> － | P31: =VLOOKUP(M31,$L$6:$P$27,2,FALSE) -> クラッシュ | Q31: =INDEX(リバース占い!AR:AR, MATCH($A31, INDEX(VALUE(TRIM(リバース占い!$AG:$AG)), 0), 0)) -> 戊癸干合 | R31: =INDEX(リバース占い!AS:AS, MATCH($A31, INDEX(VALUE(TRIM(リバース占い!$AG:$AG)), 0), 0)) | S31: =INDEX(リバース占い!AT:AT, MATCH($A31, INDEX(VALUE(TRIM(リバース占い!$AG:$AG)), 0), 0)) | T31: =VLOOKUP(Q31,$S$5:$U$10,3,FALSE) -> オトメ化 | U31: =VLOOKUP(R31,$S$5:$U$10,3,FALSE) -> #N/A | V31: =VLOOKUP(S31,$S$5:$U$10,3,FALSE) -> #N/A
A32: =YEAR(TODAY())-2 -> 2024 | B32: =INDEX(リバース占い!AV:AV, MATCH(A32, INDEX(VALUE(TRIM(リバース占い!AG:AG)), 0), 0)) -> 満天 | C32: =INDEX(リバース占い!AW:AW, MATCH(A32, INDEX(VALUE(TRIM(リバース占い!AG:AG)), 0), 0)) -> 収穫の喜び。物質や人脈などあらゆる財を蓄積し、強固な基盤を作る。 | K32: =INDEX(リバース占い!AN:AN, MATCH($A32, INDEX(VALUE(TRIM(リバース占い!$AG:$AG)), 0), 0)) -> 半会 | L32: =INDEX(リバース占い!AO:AO, MATCH($A32, INDEX(VALUE(TRIM(リバース占い!$AG:$AG)), 0), 0)) -> 半会 | M32: =INDEX(リバース占い!AP:AP, MATCH($A32, INDEX(VALUE(TRIM(リバース占い!$AG:$AG)), 0), 0)) -> 支合 | N32: =VLOOKUP(K32,$L$6:$P$27,2,FALSE) -> シナジー | O32: =VLOOKUP(L32,$L$6:$P$27,2,FALSE) -> シナジー | P32: =VLOOKUP(M32,$L$6:$P$27,2,FALSE) -> バランス | Q32: =INDEX(リバース占い!AR:AR, MATCH($A32, INDEX(VALUE(TRIM(リバース占い!$AG:$AG)), 0), 0)) | R32: =INDEX(リバース占い!AS:AS, MATCH($A32, INDEX(VALUE(TRIM(リバース占い!$AG:$AG)), 0), 0)) | S32: =INDEX(リバース占い!AT:AT, MATCH($A32, INDEX(VALUE(TRIM(リバース占い!$AG:$AG)), 0), 0)) | T32: =VLOOKUP(Q32,$S$5:$U$10,3,FALSE) -> #N/A | U32: =VLOOKUP(R32,$S$5:$U$10,3,FALSE) -> #N/A | V32: =VLOOKUP(S32,$S$5:$U$10,3,FALSE) -> #N/A
A33: =YEAR(TODAY())-1 -> 2025 | B33: =INDEX(リバース占い!AV:AV, MATCH(A33, INDEX(VALUE(TRIM(リバース占い!AG:AG)), 0), 0)) -> 静天 | C33: =INDEX(リバース占い!AW:AW, MATCH(A33, INDEX(VALUE(TRIM(リバース占い!AG:AG)), 0), 0)) -> 成果が出揃う。精神的な安定と充実の中で平和に人生を俯瞰する時期。 | K33: =INDEX(リバース占い!AN:AN, MATCH($A33, INDEX(VALUE(TRIM(リバース占い!$AG:$AG)), 0), 0)) -> － | L33: =INDEX(リバース占い!AO:AO, MATCH($A33, INDEX(VALUE(TRIM(リバース占い!$AG:$AG)), 0), 0)) -> 支合 | M33: =INDEX(リバース占い!AP:AP, MATCH($A33, INDEX(VALUE(TRIM(リバース占い!$AG:$AG)), 0), 0)) -> 半会 | N33: =VLOOKUP(K33,$L$6:$P$27,2,FALSE) -> － | O33: =VLOOKUP(L33,$L$6:$P$27,2,FALSE) -> バランス | P33: =VLOOKUP(M33,$L$6:$P$27,2,FALSE) -> シナジー | Q33: =INDEX(リバース占い!AR:AR, MATCH($A33, INDEX(VALUE(TRIM(リバース占い!$AG:$AG)), 0), 0)) | R33: =INDEX(リバース占い!AS:AS, MATCH($A33, INDEX(VALUE(TRIM(リバース占い!$AG:$AG)), 0), 0)) | S33: =INDEX(リバース占い!AT:AT, MATCH($A33, INDEX(VALUE(TRIM(リバース占い!$AG:$AG)), 0), 0)) | T33: =VLOOKUP(Q33,$S$5:$U$10,3,FALSE) -> #N/A | U33: =VLOOKUP(R33,$S$5:$U$10,3,FALSE) -> #N/A | V33: =VLOOKUP(S33,$S$5:$U$10,3,FALSE) -> #N/A
A34: =YEAR(TODAY()) -> 2026 | B34: =INDEX(リバース占い!AV:AV, MATCH(A34, INDEX(VALUE(TRIM(リバース占い!AG:AG)), 0), 0)) -> 暗天 | C34: =INDEX(リバース占い!AW:AW, MATCH(A34, INDEX(VALUE(TRIM(リバース占い!AG:AG)), 0), 0)) -> 運気下降（運の冬入り）。孤独を感じやすいが水面下の自己鍛錬が必要。 | K34: =INDEX(リバース占い!AN:AN, MATCH($A34, INDEX(VALUE(TRIM(リバース占い!$AG:$AG)), 0), 0)) -> 対冲 | L34: =INDEX(リバース占い!AO:AO, MATCH($A34, INDEX(VALUE(TRIM(リバース占い!$AG:$AG)), 0), 0)) -> － | M34: =INDEX(リバース占い!AP:AP, MATCH($A34, INDEX(VALUE(TRIM(リバース占い!$AG:$AG)), 0), 0)) -> － | N34: =VLOOKUP(K34,$L$6:$P$27,2,FALSE) -> クラッシュ | O34: =VLOOKUP(L34,$L$6:$P$27,2,FALSE) -> － | P34: =VLOOKUP(M34,$L$6:$P$27,2,FALSE) -> － | Q34: =INDEX(リバース占い!AR:AR, MATCH($A34, INDEX(VALUE(TRIM(リバース占い!$AG:$AG)), 0), 0)) | R34: =INDEX(リバース占い!AS:AS, MATCH($A34, INDEX(VALUE(TRIM(リバース占い!$AG:$AG)), 0), 0)) | S34: =INDEX(リバース占い!AT:AT, MATCH($A34, INDEX(VALUE(TRIM(リバース占い!$AG:$AG)), 0), 0)) -> 丙辛干合 | T34: =VLOOKUP(Q34,$S$5:$U$10,3,FALSE) -> #N/A | U34: =VLOOKUP(R34,$S$5:$U$10,3,FALSE) -> #N/A | V34: =VLOOKUP(S34,$S$5:$U$10,3,FALSE) -> デレ化
A35: =YEAR(TODAY())+1 -> 2027 | B35: =INDEX(リバース占い!AV:AV, MATCH(A35, INDEX(VALUE(TRIM(リバース占い!AG:AG)), 0), 0)) -> 大曇天 | C35: =INDEX(リバース占い!AW:AW, MATCH(A35, INDEX(VALUE(TRIM(リバース占い!AG:AG)), 0), 0)) -> 運命の停止（運の真冬時期）。古い価値観を手放す究極の浄化期間。 | K35: =INDEX(リバース占い!AN:AN, MATCH($A35, INDEX(VALUE(TRIM(リバース占い!$AG:$AG)), 0), 0)) -> 害 | L35: =INDEX(リバース占い!AO:AO, MATCH($A35, INDEX(VALUE(TRIM(リバース占い!$AG:$AG)), 0), 0)) -> － | M35: =INDEX(リバース占い!AP:AP, MATCH($A35, INDEX(VALUE(TRIM(リバース占い!$AG:$AG)), 0), 0)) -> － | N35: =VLOOKUP(K35,$L$6:$P$27,2,FALSE) -> ストレス | O35: =VLOOKUP(L35,$L$6:$P$27,2,FALSE) -> － | P35: =VLOOKUP(M35,$L$6:$P$27,2,FALSE) -> － | Q35: =INDEX(リバース占い!AR:AR, MATCH($A35, INDEX(VALUE(TRIM(リバース占い!$AG:$AG)), 0), 0)) | R35: =INDEX(リバース占い!AS:AS, MATCH($A35, INDEX(VALUE(TRIM(リバース占い!$AG:$AG)), 0), 0)) | S35: =INDEX(リバース占い!AT:AT, MATCH($A35, INDEX(VALUE(TRIM(リバース占い!$AG:$AG)), 0), 0)) | T35: =VLOOKUP(Q35,$S$5:$U$10,3,FALSE) -> #N/A | U35: =VLOOKUP(R35,$S$5:$U$10,3,FALSE) -> #N/A | V35: =VLOOKUP(S35,$S$5:$U$10,3,FALSE) -> #N/A
A36: =YEAR(TODAY())+2 -> 2028 | B36: =INDEX(リバース占い!AV:AV, MATCH(A36, INDEX(VALUE(TRIM(リバース占い!AG:AG)), 0), 0)) -> 雨天 | C36: =INDEX(リバース占い!AW:AW, MATCH(A36, INDEX(VALUE(TRIM(リバース占い!AG:AG)), 0), 0)) -> カルマの精算。過去の執着をすべて洗い流し、次の春への準備を整える。 | K36: =INDEX(リバース占い!AN:AN, MATCH($A36, INDEX(VALUE(TRIM(リバース占い!$AG:$AG)), 0), 0)) -> 大半会 | L36: =INDEX(リバース占い!AO:AO, MATCH($A36, INDEX(VALUE(TRIM(リバース占い!$AG:$AG)), 0), 0)) -> 同 | M36: =INDEX(リバース占い!AP:AP, MATCH($A36, INDEX(VALUE(TRIM(リバース占い!$AG:$AG)), 0), 0)) -> 準方位 | N36: =VLOOKUP(K36,$L$6:$P$27,2,FALSE) -> フィーバー | O36: =VLOOKUP(L36,$L$6:$P$27,2,FALSE) -> ブースト | P36: =VLOOKUP(M36,$L$6:$P$27,2,FALSE) -> スクラム | Q36: =INDEX(リバース占い!AR:AR, MATCH($A36, INDEX(VALUE(TRIM(リバース占い!$AG:$AG)), 0), 0)) | R36: =INDEX(リバース占い!AS:AS, MATCH($A36, INDEX(VALUE(TRIM(リバース占い!$AG:$AG)), 0), 0)) | S36: =INDEX(リバース占い!AT:AT, MATCH($A36, INDEX(VALUE(TRIM(リバース占い!$AG:$AG)), 0), 0)) | T36: =VLOOKUP(Q36,$S$5:$U$10,3,FALSE) -> #N/A | U36: =VLOOKUP(R36,$S$5:$U$10,3,FALSE) -> #N/A | V36: =VLOOKUP(S36,$S$5:$U$10,3,FALSE) -> #N/A
A37: =YEAR(TODAY())+3 -> 2029 | B37: =INDEX(リバース占い!AV:AV, MATCH(A37, INDEX(VALUE(TRIM(リバース占い!AG:AG)), 0), 0)) -> 起天 | C37: =INDEX(リバース占い!AW:AW, MATCH(A37, INDEX(VALUE(TRIM(リバース占い!AG:AG)), 0), 0)) -> 運命の幕開け。過去を断ち切り新しい種をまく開拓期。 | K37: =INDEX(リバース占い!AN:AN, MATCH($A37, INDEX(VALUE(TRIM(リバース占い!$AG:$AG)), 0), 0)) -> 破 | L37: =INDEX(リバース占い!AO:AO, MATCH($A37, INDEX(VALUE(TRIM(リバース占い!$AG:$AG)), 0), 0)) -> 準方位 | M37: =INDEX(リバース占い!AP:AP, MATCH($A37, INDEX(VALUE(TRIM(リバース占い!$AG:$AG)), 0), 0)) -> 自刑 | N37: =VLOOKUP(K37,$L$6:$P$27,2,FALSE) -> フリーズ | O37: =VLOOKUP(L37,$L$6:$P$27,2,FALSE) -> スクラム | P37: =VLOOKUP(M37,$L$6:$P$27,2,FALSE) -> セルフバトル | Q37: =INDEX(リバース占い!AR:AR, MATCH($A37, INDEX(VALUE(TRIM(リバース占い!$AG:$AG)), 0), 0)) | R37: =INDEX(リバース占い!AS:AS, MATCH($A37, INDEX(VALUE(TRIM(リバース占い!$AG:$AG)), 0), 0)) | S37: =INDEX(リバース占い!AT:AT, MATCH($A37, INDEX(VALUE(TRIM(リバース占い!$AG:$AG)), 0), 0)) | T37: =VLOOKUP(Q37,$S$5:$U$10,3,FALSE) -> #N/A | U37: =VLOOKUP(R37,$S$5:$U$10,3,FALSE) -> #N/A | V37: =VLOOKUP(S37,$S$5:$U$10,3,FALSE) -> #N/A
A38: =YEAR(TODAY())+4 -> 2030 | B38: =INDEX(リバース占い!AV:AV, MATCH(A38, INDEX(VALUE(TRIM(リバース占い!AG:AG)), 0), 0)) -> 吉祥天 | C38: =INDEX(リバース占い!AW:AW, MATCH(A38, INDEX(VALUE(TRIM(リバース占い!AG:AG)), 0), 0)) -> まいた種が芽吹き、周囲の支援を受けて着実に育つ時期。 | K38: =INDEX(リバース占い!AN:AN, MATCH($A38, INDEX(VALUE(TRIM(リバース占い!$AG:$AG)), 0), 0)) -> － | L38: =INDEX(リバース占い!AO:AO, MATCH($A38, INDEX(VALUE(TRIM(リバース占い!$AG:$AG)), 0), 0)) -> 準方位 | M38: =INDEX(リバース占い!AP:AP, MATCH($A38, INDEX(VALUE(TRIM(リバース占い!$AG:$AG)), 0), 0)) -> 害 | N38: =VLOOKUP(K38,$L$6:$P$27,2,FALSE) -> － | O38: =VLOOKUP(L38,$L$6:$P$27,2,FALSE) -> スクラム | P38: =VLOOKUP(M38,$L$6:$P$27,2,FALSE) -> ストレス | Q38: =INDEX(リバース占い!AR:AR, MATCH($A38, INDEX(VALUE(TRIM(リバース占い!$AG:$AG)), 0), 0)) | R38: =INDEX(リバース占い!AS:AS, MATCH($A38, INDEX(VALUE(TRIM(リバース占い!$AG:$AG)), 0), 0)) | S38: =INDEX(リバース占い!AT:AT, MATCH($A38, INDEX(VALUE(TRIM(リバース占い!$AG:$AG)), 0), 0)) | T38: =VLOOKUP(Q38,$S$5:$U$10,3,FALSE) -> #N/A | U38: =VLOOKUP(R38,$S$5:$U$10,3,FALSE) -> #N/A | V38: =VLOOKUP(S38,$S$5:$U$10,3,FALSE) -> #N/A
A39: =YEAR(TODAY())+5 -> 2031 | B39: =INDEX(リバース占い!AV:AV, MATCH(A39, INDEX(VALUE(TRIM(リバース占い!AG:AG)), 0), 0)) -> 弁財天 | C39: =INDEX(リバース占い!AW:AW, MATCH(A39, INDEX(VALUE(TRIM(リバース占い!AG:AG)), 0), 0)) -> 才能がパッと花開き、今後の人生を左右する重要な決定を下す発展期。 | K39: =INDEX(リバース占い!AN:AN, MATCH($A39, INDEX(VALUE(TRIM(リバース占い!$AG:$AG)), 0), 0)) -> 準方位 | L39: =INDEX(リバース占い!AO:AO, MATCH($A39, INDEX(VALUE(TRIM(リバース占い!$AG:$AG)), 0), 0)) -> 害 | M39: =INDEX(リバース占い!AP:AP, MATCH($A39, INDEX(VALUE(TRIM(リバース占い!$AG:$AG)), 0), 0)) -> － | N39: =VLOOKUP(K39,$L$6:$P$27,2,FALSE) -> スクラム | O39: =VLOOKUP(L39,$L$6:$P$27,2,FALSE) -> ストレス | P39: =VLOOKUP(M39,$L$6:$P$27,2,FALSE) -> － | Q39: =INDEX(リバース占い!AR:AR, MATCH($A39, INDEX(VALUE(TRIM(リバース占い!$AG:$AG)), 0), 0)) | R39: =INDEX(リバース占い!AS:AS, MATCH($A39, INDEX(VALUE(TRIM(リバース占い!$AG:$AG)), 0), 0)) -> 丙辛干合 | S39: =INDEX(リバース占い!AT:AT, MATCH($A39, INDEX(VALUE(TRIM(リバース占い!$AG:$AG)), 0), 0)) | T39: =VLOOKUP(Q39,$S$5:$U$10,3,FALSE) -> #N/A | U39: =VLOOKUP(R39,$S$5:$U$10,3,FALSE) -> デレ化 | V39: =VLOOKUP(S39,$S$5:$U$10,3,FALSE) -> #N/A
A40: =YEAR(TODAY())+6 -> 2032 | B40: =INDEX(リバース占い!AV:AV, MATCH(A40, INDEX(VALUE(TRIM(リバース占い!AG:AG)), 0), 0)) -> 曇天 | C40: =INDEX(リバース占い!AW:AW, MATCH(A40, INDEX(VALUE(TRIM(リバース占い!AG:AG)), 0), 0)) -> 運気の勢いに心身が追いつかない小休止。自己治癒の時期。 | K40: =INDEX(リバース占い!AN:AN, MATCH($A40, INDEX(VALUE(TRIM(リバース占い!$AG:$AG)), 0), 0)) -> 同 | L40: =INDEX(リバース占い!AO:AO, MATCH($A40, INDEX(VALUE(TRIM(リバース占い!$AG:$AG)), 0), 0)) -> 半会 | M40: =INDEX(リバース占い!AP:AP, MATCH($A40, INDEX(VALUE(TRIM(リバース占い!$AG:$AG)), 0), 0)) -> 破 | N40: =VLOOKUP(K40,$L$6:$P$27,2,FALSE) -> ブースト | O40: =VLOOKUP(L40,$L$6:$P$27,2,FALSE) -> シナジー | P40: =VLOOKUP(M40,$L$6:$P$27,2,FALSE) -> フリーズ | Q40: =INDEX(リバース占い!AR:AR, MATCH($A40, INDEX(VALUE(TRIM(リバース占い!$AG:$AG)), 0), 0)) | R40: =INDEX(リバース占い!AS:AS, MATCH($A40, INDEX(VALUE(TRIM(リバース占い!$AG:$AG)), 0), 0)) | S40: =INDEX(リバース占い!AT:AT, MATCH($A40, INDEX(VALUE(TRIM(リバース占い!$AG:$AG)), 0), 0)) | T40: =VLOOKUP(Q40,$S$5:$U$10,3,FALSE) -> #N/A | U40: =VLOOKUP(R40,$S$5:$U$10,3,FALSE) -> #N/A | V40: =VLOOKUP(S40,$S$5:$U$10,3,FALSE) -> #N/A
A41: =YEAR(TODAY())+7 -> 2033 | B41: =INDEX(リバース占い!AV:AV, MATCH(A41, INDEX(VALUE(TRIM(リバース占い!AG:AG)), 0), 0)) -> 韋駄天 | C41: =INDEX(リバース占い!AW:AW, MATCH(A41, INDEX(VALUE(TRIM(リバース占い!AG:AG)), 0), 0)) -> 運気絶頂。これまでの努力が実を結び、最高のスポットライトを浴びる。 | K41: =INDEX(リバース占い!AN:AN, MATCH($A41, INDEX(VALUE(TRIM(リバース占い!$AG:$AG)), 0), 0)) -> 支合 | L41: =INDEX(リバース占い!AO:AO, MATCH($A41, INDEX(VALUE(TRIM(リバース占い!$AG:$AG)), 0), 0)) -> － | M41: =INDEX(リバース占い!AP:AP, MATCH($A41, INDEX(VALUE(TRIM(リバース占い!$AG:$AG)), 0), 0)) -> 半会 | N41: =VLOOKUP(K41,$L$6:$P$27,2,FALSE) -> バランス | O41: =VLOOKUP(L41,$L$6:$P$27,2,FALSE) -> － | P41: =VLOOKUP(M41,$L$6:$P$27,2,FALSE) -> シナジー | Q41: =INDEX(リバース占い!AR:AR, MATCH($A41, INDEX(VALUE(TRIM(リバース占い!$AG:$AG)), 0), 0)) -> 戊癸干合 | R41: =INDEX(リバース占い!AS:AS, MATCH($A41, INDEX(VALUE(TRIM(リバース占い!$AG:$AG)), 0), 0)) | S41: =INDEX(リバース占い!AT:AT, MATCH($A41, INDEX(VALUE(TRIM(リバース占い!$AG:$AG)), 0), 0)) | T41: =VLOOKUP(Q41,$S$5:$U$10,3,FALSE) -> オトメ化 | U41: =VLOOKUP(R41,$S$5:$U$10,3,FALSE) -> #N/A | V41: =VLOOKUP(S41,$S$5:$U$10,3,FALSE) -> #N/A
A42: =YEAR(TODAY())+8 -> 2034 | B42: =INDEX(リバース占い!AV:AV, MATCH(A42, INDEX(VALUE(TRIM(リバース占い!AG:AG)), 0), 0)) -> 伏魔天 | C42: =INDEX(リバース占い!AW:AW, MATCH(A42, INDEX(VALUE(TRIM(リバース占い!AG:AG)), 0), 0)) -> 強すぎる運気の反動で迷いや摩擦が生じる。理性と現状維持が必要な嵐。 | K42: =INDEX(リバース占い!AN:AN, MATCH($A42, INDEX(VALUE(TRIM(リバース占い!$AG:$AG)), 0), 0)) -> － | L42: =INDEX(リバース占い!AO:AO, MATCH($A42, INDEX(VALUE(TRIM(リバース占い!$AG:$AG)), 0), 0)) -> 対冲 | M42: =INDEX(リバース占い!AP:AP, MATCH($A42, INDEX(VALUE(TRIM(リバース占い!$AG:$AG)), 0), 0)) -> － | N42: =VLOOKUP(K42,$L$6:$P$27,2,FALSE) -> － | O42: =VLOOKUP(L42,$L$6:$P$27,2,FALSE) -> クラッシュ | P42: =VLOOKUP(M42,$L$6:$P$27,2,FALSE) -> － | Q42: =INDEX(リバース占い!AR:AR, MATCH($A42, INDEX(VALUE(TRIM(リバース占い!$AG:$AG)), 0), 0)) | R42: =INDEX(リバース占い!AS:AS, MATCH($A42, INDEX(VALUE(TRIM(リバース占い!$AG:$AG)), 0), 0)) | S42: =INDEX(リバース占い!AT:AT, MATCH($A42, INDEX(VALUE(TRIM(リバース占い!$AG:$AG)), 0), 0)) | T42: =VLOOKUP(Q42,$S$5:$U$10,3,FALSE) -> #N/A | U42: =VLOOKUP(R42,$S$5:$U$10,3,FALSE) -> #N/A | V42: =VLOOKUP(S42,$S$5:$U$10,3,FALSE) -> #N/A
A44: 月天運 | N44: 家庭 | O44: 自分 | P44: 社会 | Q44: 家庭 | R44: 自分 | S44: 社会 | T44: 家庭 | U44: 自分 | V44: 社会
...

Sheet リバース占い
E2: 氏名 | I2: 生年 | K2: 生月 | L2: 生日 | M2: 性別 | O2: 28828 | AJ2: 数理法（％）
I3: 1981 | K3: 9 | L3: 7 | M3: 男 | AJ3: 干 | AK3: 干 数 | AL3: 星 | AN3: 日干入 単価 | AO3: 日干入 合計 | AP3: 日干 なし | AQ3: 剋線
F5: =I139 -> 25 | G5: =I141 -> 33 | H5: =H137 -> 58 | L5: =I129 -> 調舒星 | N5: =VLOOKUP(I133,$BQ$191:$BT$202,2,FALSE) -> 0 | AG5: =VLOOKUP(LEFT(L5,3),$AN$220:$AO$229,2,FALSE) -> 火 | AJ5: =VLOOKUP(AL5&$F$6,$A$155:$D$254,4,FALSE) -> 甲 | AK5: =HLOOKUP(AJ5,$BV$136:$CG$146,11,FALSE) -> 0 | AL5: =B150 -> 車騎星 | AN5: =ROUND(HLOOKUP(AJ5,$BV$147:$CG$157,11,FALSE)/$CH$157*100/IF(AK5=0,1,AK5),0) -> 0 | AO5: =ROUND(HLOOKUP(AJ5,$BV$147:$CG$157,11,FALSE)/$CH$157*100/IF(AK5=0,1,AK5),0)*AK5 -> 0 | AP5: =ROUND(HLOOKUP(AJ5,$BV$147:$CG$155,9,FALSE)/$CH$155*100,0) -> 0 | AQ5: =[1]意識と無意識!G4 -> 0 | BW5: ↓誕生日入力↓ | BX5: 性別
E6: =IF(F5<11,"戌",IF(F5<21,"申",IF(F5<31,"午",IF(F5<41,"辰",IF(F5<51,"寅","子"))))) -> 午 | F6: =VLOOKUP($F$5,$AG$140:$AN$200,8,FALSE) -> 戊 | G6: =VLOOKUP($G$5,$AG$140:$AN$200,8,FALSE) -> 丙 | H6: =VLOOKUP($H$5,$AG$140:$AN$200,8,FALSE) -> 辛 | J6: =IF(AL202=1,G130,IF(AL202=2,G131,G132)) -> 司禄星 | L6: =IF(AM202=1,H130,IF(AM202=2,H131,H132)) -> 鳳閣星 | N6: =IF(AN202=1,I130,IF(AN202=2,I131,I132)) -> 調舒星 | V6: １２天運 | W6: 内容 | AF6: =VLOOKUP(LEFT(J6,3),$AN$220:$AO$229,2,FALSE) -> 土 | AG6: =VLOOKUP(LEFT(L6,3),AN$220:$AO$229,2,FALSE) -> 火 | AH6: =VLOOKUP(LEFT(N6,3),$AN$220:$AO$229,2,FALSE) -> 火 | AJ6: =VLOOKUP(AL6&$F$6,$A$155:$D$254,4,FALSE) -> 乙 | AK6: =HLOOKUP(AJ6,$BV$136:$CG$146,11,FALSE) -> 0 | AL6: =B149 -> 牽牛星 | AN6: =ROUND(HLOOKUP(AJ6,$BV$147:$CG$157,11,FALSE)/$CH$157*100/IF(AK6=0,1,AK6),0) -> 0 | AO6: =ROUND(HLOOKUP(AJ6,$BV$147:$CG$157,11,FALSE)/$CH$157*100/IF(AK6=0,1,AK6),0)*AK6 -> 0 | AP6: =ROUND(HLOOKUP(AJ6,$BV$147:$CG$155,9,FALSE)/$CH$155*100,0) -> 0 | AQ6: =[1]意識と無意識!G5 -> 0 | BW6: =[1]五指裏干支占い!D2 -> 29836 | BX6: =[1]五指裏干支占い!E2 -> 男
E7: =IF(F5<11,"亥",IF(F5<21,"酉",IF(F5<31,"未",IF(F5<41,"巳",IF(F5<51,"卯","丑"))))) -> 未 | F7: =VLOOKUP($F$5,$AG$140:$AM$199,6,FALSE) -> 子 | G7: =VLOOKUP($G$5,$AG$140:$AM$199,6,FALSE) -> 申 | H7: =VLOOKUP($H$5,$AG$140:$AM$199,6,FALSE) -> 酉 | J7: =VLOOKUP(G133,$BQ$191:$BT$202,2,FALSE) -> 0 | L7: =H129 -> 龍高星 | N7: =VLOOKUP(H133,$BQ$191:$BT$202,2,FALSE) -> 0 | V7: 起天 | W7: 運命の幕開け。過去を断ち切り新しい種をまく開拓期。 | AG7: =VLOOKUP(LEFT(L7,3),$AN$220:$AO$229,2,FALSE) -> 水 | AJ7: =VLOOKUP(AL7&$F$6,$A$155:$D$254,4,FALSE) -> 丙 | AK7: =HLOOKUP(AJ7,$BV$136:$CG$146,11,FALSE) -> 1 | AL7: =B152 -> 龍高星 | AN7: =ROUND(HLOOKUP(AJ7,$BV$147:$CG$157,11,FALSE)/$CH$157*100/IF(AK7=0,1,AK7),0) -> 6 | AO7: =ROUND(HLOOKUP(AJ7,$BV$147:$CG$157,11,FALSE)/$CH$157*100/IF(AK7=0,1,AK7),0)*AK7 -> 6 | AP7: =ROUND(HLOOKUP(AJ7,$BV$147:$CG$155,9,FALSE)/$CH$155*100,0) -> 6 | AQ7: =[1]意識と無意識!G6 -> 5
E8: =E6&E7 -> 午未 | F8: =IF(VLOOKUP($F$5,$AG$140:$BT$200,9,FALSE)="","-",VLOOKUP($F$5,$AG$140:$BT$200,9,FALSE)) -> - | G8: =IF(VLOOKUP($G$5,$AG$140:$BT$200,9,FALSE)="","-",VLOOKUP($G$5,$AG$140:$BT$200,9,FALSE)) -> 戊 | H8: =IF(VLOOKUP($H$5,$AG$140:$BT$200,9,FALSE)="","-",VLOOKUP($H$5,$AG$140:$BT$200,9,FALSE)) -> - | K8: 父系祖父母 | O8: 母系祖父母 | V8: 吉祥天 | W8: まいた種が芽吹き、周囲の支援を受けて着実に育つ時期。 | AF8: 止まる星 | AH8: =IF(LEFT(BT138,3)="",O120,LEFT(BT138,3)) -> 司禄星 | AJ8: =VLOOKUP(AL8&$F$6,$A$155:$D$254,4,FALSE) -> 丁 | AK8: =HLOOKUP(AJ8,$BV$136:$CG$146,11,FALSE) -> 0 | AL8: =B151 -> 玉堂星 | AN8: =ROUND(HLOOKUP(AJ8,$BV$147:$CG$157,11,FALSE)/$CH$157*100/IF(AK8=0,1,AK8),0) -> 0 | AO8: =ROUND(HLOOKUP(AJ8,$BV$147:$CG$157,11,FALSE)/$CH$157*100/IF(AK8=0,1,AK8),0)*AK8 -> 0 | AP8: =ROUND(HLOOKUP(AJ8,$BV$147:$CG$155,9,FALSE)/$CH$155*100,0) -> 0 | AQ8: =[1]意識と無意識!G7 -> 0
F9: =IF(VLOOKUP($F$5,$AG$140:$BT$200,10,FALSE)="","-",VLOOKUP($F$5,$AG$140:$BT$200,10,FALSE)) -> - | G9: =IF(VLOOKUP($G$5,$AG$140:$BT$200,10,FALSE)="","-",VLOOKUP($G$5,$AG$140:$BT$200,10,FALSE)) -> 壬 | H9: =IF(VLOOKUP($H$5,$AG$140:$BT$200,10,FALSE)="","-",VLOOKUP($H$5,$AG$140:$BT$200,10,FALSE)) -> - | J9: =M126&N126 -> #N/A | K9: =IF(N126="×","",HLOOKUP(RIGHT(J9,1),BV147:CG154,8,FALSE)&" -") -> #N/A | L9: =P126&AF126 -> #N/A | M9: =IF(AF126="×","",HLOOKUP(RIGHT(L9,1),BV147:CG154,8,FALSE)) -> #N/A | N9: =AH126&AI126 -> #N/A | O9: =IF(AI126="×","",HLOOKUP(RIGHT(N9,1),BV147:CG154,8,FALSE)&" -") -> #N/A | P9: =AK126&AL126 -> #N/A | V9: 弁財天 | W9: 才能がパッと花開き、今後の人生を左右する重要な決定を下す発展期。 | AF9: =IF(AL126="×","",HLOOKUP(AL126,BV147:CG154,8,FALSE)&" -") -> #N/A | AJ9: =VLOOKUP(AL9&$F$6,$A$155:$D$254,4,FALSE) -> 戊 | AK9: =HLOOKUP(AJ9,$BV$136:$CG$146,11,FALSE) -> 2 | AL9: =B144 -> 貫索星 | AN9: =ROUND(HLOOKUP(AJ9,$BV$147:$CG$157,11,FALSE)/$CH$157*100/IF(AK9=0,1,AK9),0) -> 6 | AO9: =ROUND(HLOOKUP(AJ9,$BV$147:$CG$157,11,FALSE)/$CH$157*100/IF(AK9=0,1,AK9),0)*AK9 -> 12 | AP9: =ROUND(HLOOKUP(AJ9,$BV$147:$CG$155,9,FALSE)/$CH$155*100,0) -> 6 | AQ9: =[1]意識と無意識!G8 -> 2
F10: =VLOOKUP($F$5,$AG$140:$BT$200,11,FALSE) -> 癸 | G10: =VLOOKUP($G$5,$AG$140:$BT$200,11,FALSE) -> 庚 | H10: =VLOOKUP($H$5,$AG$140:$BT$200,11,FALSE) -> 辛 | L10: | | M10: 両親 | N10: | | V10: 曇天 | W10: 運気の勢いに心身が追いつかない小休止。自己治癒の時期。 | AF10: 義理の両親 | AJ10: =VLOOKUP(AL10&$F$6,$A$155:$D$254,4,FALSE) -> 己 | AK10: =HLOOKUP(AJ10,$BV$136:$CG$146,11,FALSE) -> 0 | AL10: =B143 -> 石門星 | AN10: =ROUND(HLOOKUP(AJ10,$BV$147:$CG$157,11,FALSE)/$CH$157*100/IF(AK10=0,1,AK10),0) -> 0 | AO10: =ROUND(HLOOKUP(AJ10,$BV$147:$CG$157,11,FALSE)/$CH$157*100/IF(AK10=0,1,AK10),0)*AK10 -> 0 | AP10: =ROUND(HLOOKUP(AJ10,$BV$147:$CG$155,9,FALSE)/$CH$155*100,0) -> 0 | AQ10: =[1]意識と無意識!G9 -> 0
E11: =E8&H11&G11 -> 午未 | G11: =IF(OR(E6=G7,E7=G7),"生月天中殺","") | H11: =IF(E6=H7,"生年天中殺",IF(E7=H7,"生年天中殺","")) | L11: =P128&AF128 -> #N/A | M11: =HLOOKUP(RIGHT(L11,1),BV147:CG154,8,FALSE)&" -" -> #N/A | N11: =AH128&AI128 -> 丁0 | O11: =HLOOKUP(RIGHT(N11,1),BV147:CG154,8,FALSE) -> #N/A | P11: =AK128&AL128 -> #N/A | V11: 韋駄天 | W11: 運気絶頂。これまでの努力が実を結び、最高のスポットライトを浴びる。 | AF11: =IF(AL128="×","",HLOOKUP(AL128,BV147:CG154,8,FALSE)&" -") -> #N/A | AG11: =AN128&AO128 -> #N/A | AH11: =IF(AO128="×","",HLOOKUP(AO128,BV147:CG154,8,FALSE)) -> #N/A | AJ11: =VLOOKUP(AL11&$F$6,$A$155:$D$254,4,FALSE) -> 庚 | AK11: =HLOOKUP(AJ11,$BV$136:$CG$146,11,FALSE) -> 1 | AL11: =B146 -> 鳳閣星 | AN11: =ROUND(HLOOKUP(AJ11,$BV$147:$CG$157,11,FALSE)/$CH$157*100/IF(AK11=0,1,AK11),0) -> 16 | AO11: =ROUND(HLOOKUP(AJ11,$BV$147:$CG$157,11,FALSE)/$CH$157*100/IF(AK11=0,1,AK11),0)*AK11 -> 16 | AP11: =ROUND(HLOOKUP(AJ11,$BV$147:$CG$155,9,FALSE)/$CH$155*100,0) -> 16 | AQ11: =[1]意識と無意識!G10 -> 1 | CF11: 1
N12: |自分 | P12: |配偶者 | V12: 伏魔天 | W12: 強すぎる運気の反動で迷いや摩擦が生じる。理性と現状維持が必要な嵐。 | AJ12: =VLOOKUP(AL12&$F$6,$A$155:$D$254,4,FALSE) -> 辛 | AK12: =HLOOKUP(AJ12,$BV$136:$CG$146,11,FALSE) -> 2 | AL12: =B145 -> 調舒星 | AN12: =ROUND(HLOOKUP(AJ12,$BV$147:$CG$157,11,FALSE)/$CH$157*100/IF(AK12=0,1,AK12),0) -> 20 | AO12: =ROUND(HLOOKUP(AJ12,$BV$147:$CG$157,11,FALSE)/$CH$157*100/IF(AK12=0,1,AK12),0)*AK12 -> 40 | AP12: =ROUND(HLOOKUP(AJ12,$BV$147:$CG$155,9,FALSE)/$CH$155*100,0) -> 42 | AQ12: =[1]意識と無意識!G11 -> 1 | CF12: 2
F13: =VLOOKUP(F5&"+"&G5,[1]大運!$H$45:$K$3644,2,FALSE) -> 半会 | G13: =VLOOKUP(F5&"+"&H5,[1]大運!$H$45:$K$3644,2,FALSE) -> 破 | H13: =VLOOKUP(H5&"+"&G5,[1]大運!$H$45:$K$3644,2,FALSE) -> 準方位 | I13: =IF(I3<1902,"誕生日が違います","") | N13: =AI130 -> 戊 | O13: =HLOOKUP(RIGHT(N13,1),BV147:CG154,8,FALSE)&" -" -> 9 - | P13: =AK130&AL130 -> 辛0 | V13: 有頂天 | W13: 第2の絶頂期。過去の縁が繋がり、周囲を巻き込み大きな成果を出す。 | AF13: =HLOOKUP(RIGHT(P13,1),BV147:CG154,8,FALSE) -> #N/A | AJ13: =VLOOKUP(AL13&$F$6,$A$155:$D$254,4,FALSE) -> 壬 | AK13: =HLOOKUP(AJ13,$BV$136:$CG$146,11,FALSE) -> 1 | AL13: =B148 -> 禄存星 | AN13: =ROUND(HLOOKUP(AJ13,$BV$147:$CG$157,11,FALSE)/$CH$157*100/IF(AK13=0,1,AK13),0) -> 17 | AO13: =ROUND(HLOOKUP(AJ13,$BV$147:$CG$157,11,FALSE)/$CH$157*100/IF(AK13=0,1,AK13),0)*AK13 -> 17 | AP13: =ROUND(HLOOKUP(AJ13,$BV$147:$CG$155,9,FALSE)/$CH$155*100,0) -> 18 | AQ13: =[1]意識と無意識!G12 -> 3 | CF13: 3
F14: =IF(OR(AND(MOD(F5,2)=0,G5-F5=1),AND(MOD(F5,2)=1,G5-F5=13),AND(MOD(F5,2)=0,H5-F5=1),AND(MOD(F5,2)=1,H5-F5=13)),"連唐","-") -> - | G14: =IF(OR(AND(MOD(G5,2)=0,F5-G5=1),AND(MOD(G5,2)=1,F5-G5=13),AND(MOD(G5,2)=0,H5-G5=1),AND(MOD(G5,2)=1,H5-G5=13)),"連唐","-") -> - | H14: =IF(OR(AND(MOD(H5,2)=0,F5-H5=1),AND(MOD(H5,2)=1,F5-H5=13),AND(MOD(H5,2)=0,G5-H5=1),AND(MOD(H5,2)=1,G5-H5=13)),"連唐","-") -> - | N14: |子供 | P14: |子供 | V14: 満天 | W14: 収穫の喜び。物質や人脈などあらゆる財を蓄積し、強固な基盤を作る。 | AJ14: =VLOOKUP(AL14&$F$6,$A$155:$D$254,4,FALSE) -> 癸 | AK14: =HLOOKUP(AJ14,$BV$136:$CG$146,11,FALSE) -> 1 | AL14: =B147 -> 司禄星 | AN14: =ROUND(HLOOKUP(AJ14,$BV$147:$CG$157,11,FALSE)/$CH$157*100/IF(AK14=0,1,AK14),0) -> 11 | AO14: =ROUND(HLOOKUP(AJ14,$BV$147:$CG$157,11,FALSE)/$CH$157*100/IF(AK14=0,1,AK14),0)*AK14 -> 11 | AP14: =ROUND(HLOOKUP(AJ14,$BV$147:$CG$155,9,FALSE)/$CH$155*100,0) -> 11 | AQ14: =[1]意識と無意識!G13 -> 3 | CF14: 4
L15: =P132&AF132 -> . | M15: =IF(OR(AF132="×",AF132="."),"",HLOOKUP(AF132,BV147:CG154,8,FALSE)&" -") | N15: =AH132&AI132 -> . | O15: =IF(OR(AI132="×",AI132=""),"",HLOOKUP(AI132,BV147:CG154,8,FALSE)&" -") | P15: =AK132&AL132 -> #N/A | V15: 静天 | W15: 成果が出揃う。精神的な安定と充実の中で平和に人生を俯瞰する時期。 | AF15: =IF(OR(AL132="×",AL132="."),"",HLOOKUP(AL132,BV147:CG154,8,FALSE)&" -") -> #N/A | AG15: =AN132&AO132 -> #N/A | AH15: =IF(OR(AO132="×",AO132="."),"",HLOOKUP(AO132,BV147:CG154,8,FALSE)) -> #N/A | AK15: =10-COUNTIF(AK5:AK14,0) -> 6 | AL15: 主観 | AN15: =AP6+AP8+AP10+AP12+AP14 -> 53 | AO15: 客観 | AP15: =AP5+AP7+AP9+AP11+AP13 -> 46 | AQ15: =SUM(BX17:BX26) -> 161 | CF15: 5
V16: 暗天 | W16: 運気下降（運の冬入り）。孤独を感じやすいが水面下の自己鍛錬が必要。 | BA16: 日運 | CA16: 構成比 | CB16: 欲求度 | CC16: 五大欲求 | CF16: 6
F17: =[1]大運!F6 -> 大１ | G17: =[1]大運!G6 -> 乙未 | H17: =[1]大運!H6 -> 1991 | I17: =[1]大運!I6 -> 10 | J17: =[1]大運!J6 -> 牽牛星 | K17: =[1]大運!K6 -> 天堂星 | L17: =[1]大運!L6 -> 害 | M17: =[1]大運!M6 -> － | ... P17: =[1]大運!P6 | V17: 大曇天 | W17: 運命の停止（運の真冬時期）。古い価値観を手放す究極の浄化期間。 | AE17: =RIGHT(AH17, 1) -> 戌 | AF17: =IF(OR($E$6=RIGHT(AM17,1),$E$7=RIGHT(AM17,1)),"殺",AG17-$I$3) -> 1 | AG17: =I3+1 -> 1982 | AH17: =VLOOKUP(AM17,[1]大運!$B$31:$C$90,2,FALSE) -> 壬戌 | AI17: =VLOOKUP($F$5&"+"&AM17,[1]大運!$H$45:$K$3644,3,FALSE) -> 禄存星 | AK17: =VLOOKUP($F$5&"+"&AM17,[1]大運!$H$45:$K$3644,4,FALSE) -> 天庫星 | AM17: =IF(MOD((AG17-1900+37),60)=0,60,MOD((AG17-1900+37),60)) -> 59 | AN17: =VLOOKUP($F$5&"+"&AM17,[1]大運!$H$45:$K$3644,2,FALSE) -> － | AO17: =VLOOKUP($G$5&"+"&AM17,[1]大運!$H$45:$K$3644,2,FALSE) -> 準方位 | AP17: =VLOOKUP($H$5&"+"&AM17,[1]大運!$H$45:$K$3644,2,FALSE) -> 害 | AQ17: =IF(OR(RIGHT(AH17,1)=$E$6,RIGHT(AH17,1)=$E$7),"殺","")&IF(ABS(RIGHT(AM17,1)-RIGHT($F$5,1))=5,"日","")&IF(ABS(RIGHT(AM17,1)-RIGHT($G$5,1))=5,"月","")&IF(ABS(RIGHT(AM17,1)-RIGHT($H$5,1))=5,"年","") | AR17: =IF($AH17="","", IFERROR(IF(COUNTIF($F$6, MID("己庚辛壬癸甲乙丙丁戊", FIND(LEFT($AH17,1), "甲乙丙丁戊己庚辛壬癸"), 1))>0, CHOOSE(INT((FIND(LEFT($AH17,1), "甲己乙庚丙辛丁壬戊癸")+1)/2), "甲己干合", "乙庚干合", "丙辛干合", "丁壬干合", "戊癸干合"), ""), "")) | AS17: =IF($AH17="","", IFERROR(IF(COUNTIF($G$6, MID("己庚辛壬癸甲乙丙丁戊", FIND(LEFT($AH17,1), "甲乙丙丁戊己庚辛壬癸"), 1))>0, CHOOSE(INT((FIND(LEFT($AH17,1), "甲己乙庚丙辛丁壬戊癸")+1)/2), "甲己干合", "乙庚干合", "丙辛干合", "丁壬干合", "戊癸干合"), ""), "")) | AT17: =IF($AH17="","", IFERROR(IF(COUNTIF($H$6, MID("己庚辛壬癸甲乙丙丁戊", FIND(LEFT($AH17,1), "甲乙丙丁戊己庚辛壬癸"), 1))>0, CHOOSE(INT((FIND(LEFT($AH17,1), "甲己乙庚丙辛丁壬戊癸")+1)/2), "甲己干合", "乙庚干合", "丙辛干合", "丁壬干合", "戊癸干合"), ""), "")) | AU17: =INDEX('12運シート'!C:C, MATCH(1, INDEX(('12運シート'!A:A=TRIM($T$42)) * ('12運シート'!B:B=TRIM(RIGHT(AE17, 1))), 0), 0)) -> 緑生 | AV17: =INDEX('12運シート'!$E:$E, MATCH(1, INDEX((TRIM('12運シート'!$A:$A)=TRIM($T$42)) * (TRIM('12運シート'!$B:$B)=TRIM(AE17)), 0), 0)) -> 吉祥天 | AW17: =VLOOKUP(AV17,$V$6:$W$18, 2, FALSE) -> まいた種が芽吹き、周囲の支援を受けて着実に育つ時期。 | AZ17: =RIGHT(BC17, 1) -> 亥 | BA17: =EOMONTH(TODAY(), -2) + 1 -> 46143 | BB17: =MOD(BA17 - DATE(2024, 1, 1), 60) + 1 -> 12 | BC17: =VLOOKUP(BB17,[1]大運!$B$31:$C$90,2,FALSE) -> 乙亥 | BD17: =VLOOKUP($F$5 & "+" & (MOD(BA17 - DATE(2024, 1, 1), 60) + 1), [1]大運!$H$45:$K$3644, 3, FALSE) -> 牽牛星 | BE17: =VLOOKUP($F$5 & "+" & (MOD(BA17 - DATE(2024, 1, 1), 60) + 1), [1]大運!$H$45:$K$3644, 4, FALSE) -> 天馳星 | BF17: =VLOOKUP($F$5 & "+" & (MOD(BA17 - DATE(2024, 1, 1), 60) + 1), [1]大運!$H$45:$K$3644, 2, FALSE) -> 準方位 | BG17: =VLOOKUP($G$5 & "+" & (MOD(BA17 - DATE(2024, 1, 1), 60) + 1), [1]大運!$H$45:$K$3644, 2, FALSE) -> 害 | BH17: =VLOOKUP($H$5 & "+" & (MOD(BA17 - DATE(2024, 1, 1), 60) + 1), [1]大運!$H$45:$K$3644, 2, FALSE) -> － | BI17: =IF($BC17="","", IFERROR(IF(COUNTIF($F$6, MID("己庚辛壬癸甲乙丙丁戊", FIND(LEFT($BC17,1), "甲乙丙丁戊己庚辛壬癸"), 1))>0, CHOOSE(INT((FIND(LEFT($BC17,1), "甲己乙庚丙辛丁壬戊癸")+1)/2), "甲己干合", "乙庚干合", "丙辛干合", "丁壬干合", "戊癸干合"), ""), "")) | BJ17: =IF($BC17="","", IFERROR(IF(COUNTIF($G$6, MID("己庚辛壬癸甲乙丙丁戊", FIND(LEFT($BC17,1), "甲乙丙丁戊己庚辛壬癸"), 1))>0, CHOOSE(INT((FIND(LEFT($BC17,1), "甲己乙庚丙辛丁壬戊癸")+1)/2), "甲己干合", "乙庚干合", "丙辛干合", "丁壬干合", "戊癸干合"), ""), "")) | BK17: =IF($BC17="","", IFERROR(IF(COUNTIF($H$6, MID("己庚辛壬癸甲乙丙丁戊", FIND(LEFT($BC17,1), "甲乙丙丁戊己庚辛壬癸"), 1))>0, CHOOSE(INT((FIND(LEFT($BC17,1), "甲己乙庚丙辛丁壬戊癸")+1)/2), "甲己干合", "乙庚干合", "丙辛干合", "丁壬干合", "戊癸干合"), ""), "")) | BL17: =INDEX('12運シート'!C:C, MATCH(1, INDEX(('12運シート'!A:A=TRIM($T$42)) * ('12運シート'!B:B=TRIM(RIGHT(AZ17, 1))), 0), 0)) -> 立花 | BM17: =INDEX('12運シート'!$E:$E, MATCH(1, INDEX((TRIM('12運シート'!$A:$A)=TRIM($T$42)) * (TRIM('12運シート'!$B:$B)=TRIM(AZ17)), 0), 0)) -> 弁財天 | BN17: =VLOOKUP(BM17,$V$6:$W$18, 2, FALSE) -> 才能がパッと花開き、今後の人生を左右する重要な決定を下す発展期。 | BQ17: 甲 | BT17: =COUNTIF($F$6:$H$10, "*"&BQ17&"*") -> 0 | BU17: =IFERROR(__xludf.DUMMYFUNCTION("IFERROR(VLOOKUP(""*""&AQ17&""*"", {""甲"",7,10,11,12,8,4,2,5,1,3,6,9;""乙"",4,8,12,11,10,7,9,6,3,1,5,2;""丙"",3,6,9,7,10,11,12,8,4,2,5,1;""丁"",1,5,2,4,8,12,11,10,7,9,6,3;""戊"",3,6,9,7,10,11,12,8,4,2,5,1;""己"",1,5,2,4,8,12,11,10,7,9,6,3;""庚"",2,5,1,3,6,9,7,10"&",11,12,8,4;""辛"",9,6,3,1,5,2,4,8,12,11,10,7;""壬"",12,8,4,2,5,1,3,6,9,7,10,11;""癸"",11,10,7,9,6,3,1,5,2,4,8,12}, FIND(REGEXREPLACE($H$7,""[^子丑寅卯辰巳午未申酉戌亥]"",""""), ""子丑寅卯辰巳午未申酉戌亥"")+1, FALSE), 0)"),3) -> 3 | BV17: =IFERROR(__xludf.DUMMYFUNCTION("IFERROR(VLOOKUP(""*""&AQ17&""*"", {""甲"",7,10,11,12,8,4,2,5,1,3,6,9;""乙"",4,8,12,11,10,7,9,6,3,1,5,2;""丙"",3,6,9,7,10,11,12,8,4,2,5,1;""丁"",1,5,2,4,8,12,11,10,7,9,6,3;""戊"",3,6,9,7,10,11,12,8,4,2,5,1;""己"",1,5,2,4,8,12,11,10,7,9,6,3;""庚"",2,5,1,3,6,9,7,10"&",11,12,8,4;""辛"",9,6,3,1,5,2,4,8,12,11,10,7;""壬"",12,8,4,2,5,1,3,6,9,7,10,11;""癸"",11,10,7,9,6,3,1,5,2,4,8,12}, FIND(REGEXREPLACE($G$7,""[^子丑寅卯辰巳午未申酉戌亥]"",""""), ""子丑寅卯辰巳午未申酉戌亥"")+1, FALSE), 0)"),1) -> 1 | BW17: =IFERROR(__xludf.DUMMYFUNCTION("IFERROR(VLOOKUP(""*""&AQ17&""*"", {""甲"",7,10,11,12,8,4,2,5,1,3,6,9;""乙"",4,8,12,11,10,7,9,6,3,1,5,2;""丙"",3,6,9,7,10,11,12,8,4,2,5,1;""丁"",1,5,2,4,8,12,11,10,7,9,6,3;""戊"",3,6,9,7,10,11,12,8,4,2,5,1;""己"",1,5,2,4,8,12,11,10,7,9,6,3;""庚"",2,5,1,3,6,9,7,10"&",11,12,8,4;""辛"",9,6,3,1,5,2,4,8,12,11,10,7;""壬"",12,8,4,2,5,1,3,6,9,7,10,11;""癸"",11,10,7,9,6,3,1,5,2,4,8,12}, FIND(REGEXREPLACE($F$7,""[^子丑寅卯辰巳午未申酉戌亥]"",""""), ""子丑寅卯辰巳午未申酉戌亥"")+1, FALSE), 0)"),7) -> 7 | BX17: =BT17 * (BU17 + BV17 + BW17) -> 0 | BY17: 木 | BZ17: =SUM(BX17:BX18) -> 0 | CA17: =BZ17/$BZ$22*100 -> 0 | CB17: =ROUND((BZ17 / MAX($BZ$17:$BZ$21)) * 10, 0) -> 0 | CC17: 生存の欲求 | CD17: システムの安全維持・リスク回避・保守 | CF17: 7
F18: =[1]大運!F7 -> 大２ | G18: =[1]大運!G7 -> 甲午 | H18: =[1]大運!H7 -> 2001 | I18: =[1]大運!I7 -> 20 | J18: =[1]大運!J7 -> 車騎星 | K18: =[1]大運!K7 -> 天将星 | L18: =[1]大運!L7 -> 天剋地冲 | M18: =[1]大運!M7 -> － | ... P18: =[1]大運!P7 | V18: 雨天 | W18: カルマの精算。過去の執着をすべて洗い流し、次の春への準備を整える。 | AE18: =RIGHT(AH18, 1) -> 亥 | AF18: =IF(OR($E$6=RIGHT(AM18,1),$E$7=RIGHT(AM18,1)),"殺",AG18-$I$3) -> 2 | AG18: =AG17+1 -> 1983 | AH18: =VLOOKUP(AM18,[1]大運!$B$31:$C$90,2,FALSE) -> 癸亥 | AI18: =VLOOKUP($F$5&"+"&AM18,[1]大運!$H$45:$K$3644,3,FALSE) -> 司禄星 | AK18: =VLOOKUP($F$5&"+"&AM18,[1]大運!$H$45:$K$3644,4,FALSE) -> 天馳星 | AM18: =IF(MOD((AG18-1900+37),60)=0,60,MOD((AG18-1900+37),60)) -> 60 | AN18: =VLOOKUP($F$5&"+"&AM18,[1]大運!$H$45:$K$3644,2,FALSE) -> 準方位 | AO18: =VLOOKUP($G$5&"+"&AM18,[1]大運!$H$45:$K$3644,2,FALSE) -> 害 | AP18: =VLOOKUP($H$5&"+"&AM18,[1]大運!$H$45:$K$3644,2,FALSE) -> － | AQ18: =IF(OR(RIGHT(AH19,1)=$E$6,RIGHT(AH19,1)=$E$7),"殺","")&IF(ABS(RIGHT(AM19,1)-RIGHT($F$5,1))=5,"日","")&IF(ABS(RIGHT(AM19,1)-RIGHT($G$5,1))=5,"月","")&IF(ABS(RIGHT(AM19,1)-RIGHT($H$5,1))=5,"年","") | AR18: =IF($AH18="","", IFERROR(IF(COUNTIF($F$6, MID("己庚辛壬癸甲乙丙丁戊", FIND(LEFT($AH18,1), "甲乙丙丁戊己庚辛壬癸"), 1))>0, CHOOSE(INT((FIND(LEFT($AH18,1), "甲己乙庚丙辛丁壬戊癸")+1)/2), "甲己干合", "乙庚干合", "丙辛干合", "丁壬干合", "戊癸干合"), ""), "")) -> 戊癸干合 | AS18: =IF($AH18="","", IFERROR(IF(COUNTIF($G$6, MID("己庚辛壬癸甲乙丙丁戊", FIND(LEFT($AH18,1), "甲乙丙丁戊己庚辛壬癸"), 1))>0, CHOOSE(INT((FIND(LEFT($AH18,1), "甲己乙庚丙辛丁壬戊癸")+1)/2), "甲己干合", "乙庚干合", "丙辛干合", "丁壬干合", "戊癸干合"), ""), "")) | AT18: =IF($AH18="","", IFERROR(IF(COUNTIF($H$6, MID("己庚辛壬癸甲乙丙丁戊", FIND(LEFT($AH18,1), "甲乙丙丁戊己庚辛壬癸"), 1))>0, CHOOSE(INT((FIND(LEFT($AH18,1), "甲己乙庚丙辛丁壬戊癸")+1)/2), "甲己干合", "乙庚干合", "丙辛干合", "丁壬干合", "戊癸干合"), ""), "")) | AU18: =INDEX('12運シート'!C:C, MATCH(1, INDEX(('12運シート'!A:A=TRIM($T$42)) * ('12運シート'!B:B=TRIM(RIGHT(AE18, 1))), 0), 0)) -> 立花 | AV18: =INDEX('12運シート'!$E:$E, MATCH(1, INDEX((TRIM('12運シート'!$A:$A)=TRIM($T$42)) * (TRIM('12運シート'!$B:$B)=TRIM(AE18)), 0), 0)) -> 弁財天 | AW18: =VLOOKUP(AV18,$V$6:$W$18, 2, FALSE) -> 才能がパッと花開き、今後の人生を左右する重要な決定を下す発展期。 | AZ18: =RIGHT(BC18, 1) -> 子 | BA18: =BA17+1 -> 46144 | BB18: =MOD(BA18 - DATE(2024, 1, 1), 60) + 1 -> 13 | BC18: =VLOOKUP(BB18,[1]大運!$B$31:$C$90,2,FALSE) -> 丙子 | BD18: =VLOOKUP($F$5 & "+" & (MOD(BA18 - DATE(2024, 1, 1), 60) + 1), [1]大運!$H$45:$K$3644, 3, FALSE) -> 龍高星 | BE18: =VLOOKUP($F$5 & "+" & (MOD(BA18 - DATE(2024, 1, 1), 60) + 1), [1]大運!$H$45:$K$3644, 4, FALSE) -> 天報星 | BF18: =VLOOKUP($F$5 & "+" & (MOD(BA18 - DATE(2024, 1, 1), 60) + 1), [1]大運!$H$45:$K$3644, 2, FALSE) -> 同 | BG18: =VLOOKUP($G$5 & "+" & (MOD(BA18 - DATE(2024, 1, 1), 60) + 1), [1]大運!$H$45:$K$3644, 2, FALSE) -> 大半会 | BH18: =VLOOKUP($H$5 & "+" & (MOD(BA18 - DATE(2024, 1, 1), 60) + 1), [1]大運!$H$45:$K$3644, 2, FALSE) -> 破 | BI18: =IF($BC18="","", IFERROR(IF(COUNTIF($F$6, MID("己庚辛壬癸甲乙丙丁戊", FIND(LEFT($BC18,1), "甲乙丙丁戊己庚辛壬癸"), 1))>0, CHOOSE(INT((FIND(LEFT($BC18,1), "甲己乙庚丙辛丁壬戊癸")+1)/2), "甲己干合", "乙庚干合", "丙辛干合", "丁壬干合", "戊癸干合"), ""), "")) | BJ18: =IF($BC18="","", IFERROR(IF(COUNTIF($G$6, MID("己庚辛壬癸甲乙丙丁戊", FIND(LEFT($BC18,1), "甲乙丙丁戊己庚辛壬癸"), 1))>0, CHOOSE(INT((FIND(LEFT($BC18,1), "甲己乙庚丙辛丁壬戊癸")+1)/2), "甲己干合", "乙庚干合", "丙辛干合", "丁壬干合", "戊癸干合"), ""), "")) | BK18: =IF($BC18="","", IFERROR(IF(COUNTIF($H$6, MID("己庚辛壬癸甲乙丙丁戊", FIND(LEFT($BC18,1), "甲乙丙丁戊己庚辛壬癸"), 1))>0, CHOOSE(INT((FIND(LEFT($BC18,1), "甲己乙庚丙辛丁壬戊癸")+1)/2), "甲己干合", "乙庚干合", "丙辛干合", "丁壬干合", "戊癸干合"), ""), "")) -> 丙辛干合 | BL18: =INDEX('12運シート'!C:C, MATCH(1, INDEX(('12運シート'!A:A=TRIM($T$42)) * ('12運シート'!B:B=TRIM(RIGHT(AZ18, 1))), 0), 0)) -> 健弱 | BM18: =INDEX('12運シート'!$E:$E, MATCH(1, INDEX((TRIM('12運シート'!$A:$A)=TRIM($T$42)) * (TRIM('12運シート'!$B:$B)=TRIM(AZ18)), 0), 0)) -> 曇天 | BN18: =VLOOKUP(BM18,$V$6:$W$18, 2, FALSE) -> 運気の勢いに心身が追いつかない小休止。自己治癒の時期。 | BQ18: 乙 | BT18: =COUNTIF($F$6:$H$10, "*"&BQ18&"*") -> 0 | BU18: =IFERROR(__xludf.DUMMYFUNCTION("IFERROR(VLOOKUP(""*""&AQ18&""*"", {""甲"",7,10,11,12,8,4,2,5,1,3,6,9;""乙"",4,8,12,11,10,7,9,6,3,1,5,2;""丙"",3,6,9,7,10,11,12,8,4,2,5,1;""丁"",1,5,2,4,8,12,11,10,7,9,6,3;""戊"",3,6,9,7,10,11,12,8,4,2,5,1;""己"",1,5,2,4,8,12,11,10,7,9,6,3;""庚"",2,5,1,3,6,9,7,10"&",11,12,8,4;""辛"",9,6,3,1,5,2,4,8,12,11,10,7;""壬"",12,8,4,2,5,1,3,6,9,7,10,11;""癸"",11,10,7,9,6,3,1,5,2,4,8,12}, FIND(REGEXREPLACE($H$7,""[^子丑寅卯辰巳午未申酉戌亥]"",""""), ""子丑寅卯辰巳午未申酉戌亥"")+1, FALSE), 0)"),1) -> 1 | BV18: =IFERROR(__xludf.DUMMYFUNCTION("IFERROR(VLOOKUP(""*""&AQ18&""*"", {""甲"",7,10,11,12,8,4,2,5,1,3,6,9;""乙"",4,8,12,11,10,7,9,6,3,1,5,2;""丙"",3,6,9,7,10,11,12,8,4,2,5,1;""丁"",1,5,2,4,8,12,11,10,7,9,6,3;""戊"",3,6,9,7,10,11,12,8,4,2,5,1;""己"",1,5,2,4,8,12,11,10,7,9,6,3;""庚"",2,5,1,3,6,9,7,10"&",11,12,8,4;""辛"",9,6,3,1,5,2,4,8,12,11,10,7;""壬"",12,8,4,2,5,1,3,6,9,7,10,11;""癸"",11,10,7,9,6,3,1,5,2,4,8,12}, FIND(REGEXREPLACE($G$7,""[^子丑寅卯辰巳午未申酉戌亥]"",""""), ""子丑寅卯辰巳午未申酉戌亥"")+1, FALSE), 0)"),3) -> 3 | BW18: =IFERROR(__xludf.DUMMYFUNCTION("IFERROR(VLOOKUP(""*""&AQ18&""*"", {""甲"",7,10,11,12,8,4,2,5,1,3,6,9;""乙"",4,8,12,11,10,7,9,6,3,1,5,2;""丙"",3,6,9,7,10,11,12,8,4,2,5,1;""丁"",1,5,2,4,8,12,11,10,7,9,6,3;""戊"",3,6,9,7,10,11,12,8,4,2,5,1;""己"",1,5,2,4,8,12,11,10,7,9,6,3;""庚"",2,5,1,3,6,9,7,10"&",11,12,8,4;""辛"",9,6,3,1,5,2,4,8,12,11,10,7;""壬"",12,8,4,2,5,1,3,6,9,7,10,11;""癸"",11,10,7,9,6,3,1,5,2,4,8,12}, FIND(REGEXREPLACE($F$7,""[^子丑寅卯辰巳午未申酉戌亥]"",""""), ""子丑寅卯辰巳午未申酉戌亥"")+1, FALSE), 0)"),4) -> 4 | BX18: =BT18 * (BU18 + BV18 + BW18) -> 0 | BY18: 火 | BZ18: =SUM(BX19:BX20) -> 9 | CA18: =BZ18/$BZ$22*100 -> 5.5900621 | CB18: =ROUND((BZ18 / MAX($BZ$17:$BZ$21)) * 10, 0) -> 1 | CC18: 楽しみの欲求 | CD18: 自己表現・遊び・学習の喜び・共鳴 | CF18: 8
F19: =[1]大運!F8 -> 大３ | G19: =[1]大運!G8 -> 癸巳 | H19: =[1]大運!H8 -> 2011 | I19: =[1]大運!I8 -> 30 | J19: =[1]大運!J8 -> 司禄星 | K19: =[1]大運!K8 -> 天禄星 | L19: =[1]大運!L8 -> － | M19: =[1]大運!M8 -> 支合 | ... P19: =[1]大運!P8 -> 日干 | AE19: =RIGHT(AH19, 1) -> 子 | AF19: =IF(OR($E$6=RIGHT(AM19,1),$E$7=RIGHT(AM19,1)),"殺",AG19-$I$3) -> 3 | AG19: =AG18+1 -> 1984 | AH19: =VLOOKUP(AM19,[1]大運!$B$31:$C$90,2,FALSE) -> 甲子 | AI19: =VLOOKUP($F$5&"+"&AM19,[1]大運!$H$45:$K$3644,3,FALSE) -> 車騎星 | AK19: =VLOOKUP($F$5&"+"&AM19,[1]大運!$H$45:$K$3644,4,FALSE) -> 天報星 | AM19: =IF(MOD((AG19-1900+37),60)=0,60,MOD((AG19-1900+37),60)) -> 1 | AN19: =VLOOKUP($F$5&"+"&AM19,[1]大運!$H$45:$K$3644,2,FALSE) -> 同 | AO19: =VLOOKUP($G$5&"+"&AM19,[1]大運!$H$45:$K$3644,2,FALSE) -> 半会 | AP19: =VLOOKUP($H$5&"+"&AM19,[1]大運!$H$45:$K$3644,2,FALSE) -> 破 | AQ19: =IF(OR(RIGHT(AH20,1)=$E$6,RIGHT(AH20,1)=$E$7),"殺","")&IF(ABS(RIGHT(AM20,1)-RIGHT($F$5,1))=5,"日","")&IF(ABS(RIGHT(AM20,1)-RIGHT($G$5,1))=5,"月","")&IF(ABS(RIGHT(AM20,1)-RIGHT($H$5,1))=5,"年","") | AR19: =IF($AH19="","", IFERROR(IF(COUNTIF($F$6, MID("己庚辛壬癸甲乙丙丁戊", FIND(LEFT($AH19,1), "甲乙丙丁戊己庚辛壬癸"), 1))>0, CHOOSE(INT((FIND(LEFT($AH19,1), "甲己乙庚丙辛丁壬戊癸")+1)/2), "甲己干合", "乙庚干合", "丙辛干合", "丁壬干合", "戊癸干合"), ""), "")) | AS19: =IF($AH19="","", IFERROR(IF(COUNTIF($G$6, MID("己庚辛壬癸甲乙丙丁戊", FIND(LEFT($AH19,1), "甲乙丙丁戊己庚辛壬癸"), 1))>0, CHOOSE(INT((FIND(LEFT($AH19,1), "甲己乙庚丙辛丁壬戊癸")+1)/2), "甲己干合", "乙庚干合", "丙辛干合", "丁壬干合", "戊癸干合"), ""), "")) | AT19: =IF($AH19="","", IFERROR(IF(COUNTIF($H$6, MID("己庚辛壬癸甲乙丙丁戊", FIND(LEFT($AH19,1), "甲乙丙丁戊己庚辛壬癸"), 1))>0, CHOOSE(INT((FIND(LEFT($AH19,1), "甲己乙庚丙辛丁壬戊癸")+1)/2), "甲己干合", "乙庚干合", "丙辛干合", "丁壬干合", "戊癸干合"), ""), "")) | AU19: =INDEX('12運シート'!C:C, MATCH(1, INDEX(('12運シート'!A:A=TRIM($T$42)) * ('12運シート'!B:B=TRIM(RIGHT(AE19, 1))), 0), 0)) -> 健弱 | AV19: =INDEX('12運シート'!$E:$E, MATCH(1, INDEX((TRIM('12運シート'!$A:$A)=TRIM($T$42)) * (TRIM('12運シート'!$B:$B)=TRIM(AE19)), 0), 0)) -> 曇天 | AW19: =VLOOKUP(AV19,$V$6:$W$18, 2, FALSE) -> 運気の勢いに心身が追いつかない小休止。自己治癒の時期。 | AZ19: =RIGHT(BC19, 1) -> 丑 | BA19: =BA18+1 -> 46145 | BB19: =MOD(BA19 - DATE(2024, 1, 1), 60) + 1 -> 14 | BC19: =VLOOKUP(BB19,[1]大運!$B$31:$C$90,2,FALSE) -> 丁丑 | BD19: =VLOOKUP($F$5 & "+" & (MOD(BA19 - DATE(2024, 1, 1), 60) + 1), [1]大運!$H$45:$K$3644, 3, FALSE) -> 玉堂星 | BE19: =VLOOKUP($F$5 & "+" & (MOD(BA19 - DATE(2024, 1, 1), 60) + 1), [1]大運!$H$45:$K$3644, 4, FALSE) -> 天印星 | BF19: =VLOOKUP($F$5 & "+" & (MOD(BA19 - DATE(2024, 1, 1), 60) + 1), [1]大運!$H$45:$K$3644, 2, FALSE) -> 支合 | BG19: =VLOOKUP($G$5 & "+" & (MOD(BA19 - DATE(2024, 1, 1), 60) + 1), [1]大運!$H$45:$K$3644, 2, FALSE) -> － | BH19: =VLOOKUP($H$5 & "+" & (MOD(BA19 - DATE(2024, 1, 1), 60) + 1), [1]大運!$H$45:$K$3644, 2, FALSE) -> 半会 | BI19: =IF($BC19="","", IFERROR(IF(COUNTIF($F$6, MID("己庚辛壬癸甲乙丙丁戊", FIND(LEFT($BC19,1), "甲乙丙丁戊己庚辛壬癸"), 1))>0, CHOOSE(INT((FIND(LEFT($BC19,1), "甲己乙庚丙辛丁壬戊癸")+1)/2), "甲己干合", "乙庚干合", "丙辛干合", "丁壬干合", "戊癸干合"), ""), "")) | BJ19: =IF($BC19="","", IFERROR(IF(COUNTIF($G$6, MID("己庚辛壬癸甲乙丙丁戊", FIND(LEFT($BC19,1), "甲乙丙丁戊己庚辛壬癸"), 1))>0, CHOOSE(INT((FIND(LEFT($BC19,1), "甲己乙庚丙辛丁壬戊癸")+1)/2), "甲己干合", "乙庚干合", "丙辛干合", "丁壬干合", "戊癸干合"), ""), "")) | BK19: =IF($BC19="","", IFERROR(IF(COUNTIF($H$6, MID("己庚辛壬癸甲乙丙丁戊", FIND(LEFT($BC19,1), "甲乙丙丁戊己庚辛壬癸"), 1))>0, CHOOSE(INT((FIND(LEFT($BC19,1), "甲己乙庚丙辛丁壬戊癸")+1)/2), "甲己干合", "乙庚干合", "丙辛干合", "丁壬干合", "戊癸干合"), ""), "")) | BL19: =INDEX('12運シート'!C:C, MATCH(1, INDEX(('12運シート'!A:A=TRIM($T$42)) * ('12運シート'!B:B=TRIM(RIGHT(AZ19, 1))), 0), 0)) -> 達成 | BM19: =INDEX('12運シート'!$E:$E, MATCH(1, INDEX((TRIM('12運シート'!$A:$A)=TRIM($T$42)) * (TRIM('12運シート'!$B:$B)=TRIM(AZ19)), 0), 0)) -> 韋駄天 | BN19: =VLOOKUP(BM19,$V$6:$W$18, 2, FALSE) -> 運気絶頂。これまでの努力が実を結び、最高のスポットライトを浴びる。 | BQ19: 丙 | BT19: =COUNTIF($F$6:$H$10, "*"&BQ19&"*") -> 1 | BU19: =IFERROR(__xludf.DUMMYFUNCTION("IFERROR(VLOOKUP(""*""&AQ19&""*"", {""甲"",7,10,11,12,8,4,2,5,1,3,6,9;""乙"",4,8,12,11,10,7,9,6,3,1,5,2;""丙"",3,6,9,7,10,11,12,8,4,2,5,1;""丁"",1,5,2,4,8,12,11,10,7,9,6,3;""戊"",3,6,9,7,10,11,12,8,4,2,5,1;""己"",1,5,2,4,8,12,11,10,7,9,6,3;""庚"",2,5,1,3,6,9,7,10"&",11,12,8,4;""辛"",9,6,3,1,5,2,4,8,12,11,10,7;""壬"",12,8,4,2,5,1,3,6,9,7,10,11;""癸"",11,10,7,9,6,3,1,5,2,4,8,12}, FIND(REGEXREPLACE($H$7,""[^子丑寅卯辰巳午未申酉戌亥]"",""""), ""子丑寅卯辰巳午未申酉戌亥"")+1, FALSE), 0)"),2) -> 2 | BV19: =IFERROR(__xludf.DUMMYFUNCTION("IFERROR(VLOOKUP(""*""&AQ19&""*"", {""甲"",7,10,11,12,8,4,2,5,1,3,6,9;""乙"",4,8,12,11,10,7,9,6,3,1,5,2;""丙"",3,6,9,7,10,11,12,8,4,2,5,1;""丁"",1,5,2,4,8,12,11,10,7,9,6,3;""戊"",3,6,9,7,10,11,12,8,4,2,5,1;""己"",1,5,2,4,8,12,11,10,7,9,6,3;""庚"",2,5,1,3,6,9,7,10"&",11,12,8,4;""辛"",9,6,3,1,5,2,4,8,12,11,10,7;""壬"",12,8,4,2,5,1,3,6,9,7,10,11;""癸"",11,10,7,9,6,3,1,5,2,4,8,12}, FIND(REGEXREPLACE($G$7,""[^子丑寅卯辰巳午未申酉戌亥]"",""""), ""子丑寅卯辰巳午未申酉戌亥"")+1, FALSE), 0)"),4) -> 4 | BW19: =IFERROR(__xludf.DUMMYFUNCTION("IFERROR(VLOOKUP(""*""&AQ19&""*"", {""甲"",7,10,11,12,8,4,2,5,1,3,6,9;""乙"",4,8,12,11,10,7,9,6,3,1,5,2;""丙"",3,6,9,7,10,11,12,8,4,2,5,1;""丁"",1,5,2,4,8,12,11,10,7,9,6,3;""戊"",3,6,9,7,10,11,12,8,4,2,5,1;""己"",1,5,2,4,8,12,11,10,7,9,6,3;""庚"",2,5,1,3,6,9,7,10"&",11,12,8,4;""辛"",9,6,3,1,5,2,4,8,12,11,10,7;""壬"",12,8,4,2,5,1,3,6,9,7,10,11;""癸"",11,10,7,9,6,3,1,5,2,4,8,12}, FIND(REGEXREPLACE($F$7,""[^子丑寅卯辰巳午未申酉戌亥]"",""""), ""子丑寅卯辰巳午未申酉戌亥"")+1, FALSE), 0)"),3) -> 3 | BX19: =BT19 * (BU19 + BV19 + BW19) -> 9 | BY19: 土 | BZ19: =SUM(BX21:BX22) -> 18 | CA19: =BZ19/$BZ$22*100 -> 11.180124 | CB19: =ROUND((BZ19 / MAX($BZ$17:$BZ$21)) * 10, 0) -> 2 | CC19: 愛・所属の欲求 | CD19: 蓄積・集団への帰属・他者との繋がり | CF19: 9
F20: =[1]大運!F9 -> 大４ | G20: =[1]大運!G9 -> 壬辰 | H20: =[1]大運!H9 -> 2021 | I20: =[1]大運!I9 -> 40 | J20: =[1]大運!J9 -> 禄存星 | K20: =[1]大運!K9 -> 天南星 | L20: =[1]大運!L9 -> 半会 | M20: =[1]大運!M9 -> 半会 | ... P20: =[1]大運!P9 | AE20: =RIGHT(AH20, 1) -> 丑 | AF20: =IF(OR($E$6=RIGHT(AM20,1),$E$7=RIGHT(AM20,1)),"殺",AG20-$I$3) -> 4 | AG20: =AG19+1 -> 1985 | AH20: =VLOOKUP(AM20,[1]大運!$B$31:$C$90,2,FALSE) -> 乙丑 | AI20: =VLOOKUP($F$5&"+"&AM20,[1]大運!$H$45:$K$3644,3,FALSE) -> 牽牛星 | AK20: =VLOOKUP($F$5&"+"&AM20,[1]大運!$H$45:$K$3644,4,FALSE) -> 天印星 | AM20: =IF(MOD((AG20-1900+37),60)=0,60,MOD((AG20-1900+37),60)) -> 2 | AN20: =VLOOKUP($F$5&"+"&AM20,[1]大運!$H$45:$K$3644,2,FALSE) -> 支合 | AO20: =VLOOKUP($G$5&"+"&AM20,[1]大運!$H$45:$K$3644,2,FALSE) -> － | AP20: =VLOOKUP($H$5&"+"&AM20,[1]大運!$H$45:$K$3644,2,FALSE) -> 半会 | AQ20: =IF(OR(RIGHT(AH21,1)=$E$6,RIGHT(AH21,1)=$E$7),"殺","")&IF(ABS(RIGHT(AM21,1)-RIGHT($F$5,1))=5,"日","")&IF(ABS(RIGHT(AM21,1)-RIGHT($G$5,1))=5,"月","")&IF(ABS(RIGHT(AM21,1)-RIGHT($H$5,1))=5,"年","") -> 年 | AR20: =IF($AH20="","", IFERROR(IF(COUNTIF($F$6, MID("己庚辛壬癸甲乙丙丁戊", FIND(LEFT($AH20,1), "甲乙丙丁戊己庚辛壬癸"), 1))>0, CHOOSE(INT((FIND(LEFT($AH20,1), "甲己乙庚丙辛丁壬戊癸")+1)/2), "甲己干合", "乙庚干合", "丙辛干合", "丁壬干合", "戊癸干合"), ""), "")) | AS20: =IF($AH20="","", IFERROR(IF(COUNTIF($G$6, MID("己庚辛壬癸甲乙丙丁戊", FIND(LEFT($AH20,1), "甲乙丙丁戊己庚辛壬癸"), 1))>0, CHOOSE(INT((FIND(LEFT($AH20,1), "甲己乙庚丙辛丁壬戊癸")+1)/2), "甲己干合", "乙庚干合", "丙辛干合", "丁壬干合", "戊癸干合"), ""), "")) | AT20: =IF($AH20="","", IFERROR(IF(COUNTIF($H$6, MID("己庚辛壬癸甲乙丙丁戊", FIND(LEFT($AH20,1), "甲乙丙丁戊己庚辛壬癸"), 1))>0, CHOOSE(INT((FIND(LEFT($AH20,1), "甲己乙庚丙辛丁壬戊癸")+1)/2), "甲己干合", "乙庚干合", "丙辛干合", "丁壬干合", "戊癸干合"), ""), "")) | AU20: =INDEX('12運シート'!C:C, MATCH(1, INDEX(('12運シート'!A:A=TRIM($T$42)) * ('12運シート'!B:B=TRIM(RIGHT(AE20, 1))), 0), 0)) -> 達成 | AV20: =INDEX('12運シート'!$E:$E, MATCH(1, INDEX((TRIM('12運シート'!$A:$A)=TRIM($T$42)) * (TRIM('12運シート'!$B:$B)=TRIM(AE20)), 0), 0)) -> 韋駄天 | AW20: =VLOOKUP(AV20,$V$6:$W$18, 2, FALSE) -> 運気絶頂。これまでの努力が実を結び、最高のスポットライトを浴びる。 | AZ20: =RIGHT(BC20, 1) -> 寅 | BA20: =BA19+1 -> 46146 | BB20: =MOD(BA20 - DATE(2024, 1, 1), 60) + 1 -> 15 | BC20: =VLOOKUP(BB20,[1]大運!$B$31:$C$90,2,FALSE) -> 戊寅 | BD20: =VLOOKUP($F$5 & "+" & (MOD(BA20 - DATE(2024, 1, 1), 60) + 1), [1]大運!$H$45:$K$3644, 3, FALSE) -> 貫索星 | BE20: =VLOOKUP($F$5 & "+" & (MOD(BA20 - DATE(2024, 1, 1), 60) + 1), [1]大運!$H$45:$K$3644, 4, FALSE) -> 天貴星 | BF20: =VLOOKUP($F$5 & "+" & (MOD(BA20 - DATE(2024, 1, 1), 60) + 1), [1]大運!$H$45:$K$3644, 2, FALSE) -> － | BG20: =VLOOKUP($G$5 & "+" & (MOD(BA20 - DATE(2024, 1, 1), 60) + 1), [1]大運!$H$45:$K$3644, 2, FALSE) -> 対冲 | BH20: =VLOOKUP($H$5 & "+" & (MOD(BA20 - DATE(2024, 1, 1), 60) + 1), [1]大運!$H$45:$K$3644, 2, FALSE) -> － | BI20: =IF($BC20="","", IFERROR(IF(COUNTIF($F$6, MID("己庚辛壬癸甲乙丙丁戊", FIND(LEFT($BC20,1), "甲乙丙丁戊己庚辛壬癸"), 1))>0, CHOOSE(INT((FIND(LEFT($BC20,1), "甲己乙庚丙辛丁壬戊癸")+1)/2), "甲己干合", "乙庚干合", "丙辛干合", "丁壬干合", "戊癸干合"), ""), "")) | BJ20: =IF($BC20="","", IFERROR(IF(COUNTIF($G$6, MID("己庚辛壬癸甲乙丙丁戊", FIND(LEFT($BC20,1), "甲乙丙丁戊己庚辛壬癸"), 1))>0, CHOOSE(INT((FIND(LEFT($BC20,1), "甲己乙庚丙辛丁壬戊癸")+1)/2), "甲己干合", "乙庚干合", "丙辛干合", "丁壬干合", "戊癸干合"), ""), "")) | BK20: =IF($BC20="","", IFERROR(IF(COUNTIF($H$6, MID("己庚辛壬癸甲乙丙丁戊", FIND(LEFT($BC20,1), "甲乙丙丁戊己庚辛壬癸"), 1))>0, CHOOSE(INT((FIND(LEFT($BC20,1), "甲己乙庚丙辛丁壬戊癸")+1)/2), "甲己干合", "乙庚干合", "丙辛干合", "丁壬干合", "戊癸干合"), ""), "")) | BL20: =INDEX('12運シート'!C:C, MATCH(1, INDEX(('12運シート'!A:A=TRIM($T$42)) * ('12運シート'!B:B=TRIM(RIGHT(AZ20, 1))), 0), 0)) -> 乱気 | BM20: =INDEX('12運シート'!$E:$E, MATCH(1, INDEX((TRIM('12運シート'!$A:$A)=TRIM($T$42)) * (TRIM('12運シート'!$B:$B)=TRIM(AZ20)), 0), 0)) -> 伏魔天 | BN20: =VLOOKUP(BM20,$V$6:$W$18, 2, FALSE) -> 強すぎる運気の反動で迷いや摩擦が生じる。理性と現状維持が必要な嵐。 | BQ20: 丁 | BT20: =COUNTIF($F$6:$H$10, "*"&BQ20&"*") -> 0 | BU20: =IFERROR(__xludf.DUMMYFUNCTION("IFERROR(VLOOKUP(""*""&AQ20&""*"", {""甲"",7,10,11,12,8,4,2,5,1,3,6,9;""乙"",4,8,12,11,10,7,9,6,3,1,5,2;""丙"",3,6,9,7,10,11,12,8,4,2,5,1;""丁"",1,5,2,4,8,12,11,10,7,9,6,3;""戊"",3,6,9,7,10,11,12,8,4,2,5,1;""己"",1,5,2,4,8,12,11,10,7,9,6,3;""庚"",2,5,1,3,6,9,7,10"&",11,12,8,4;""辛"",9,6,3,1,5,2,4,8,12,11,10,7;""壬"",12,8,4,2,5,1,3,6,9,7,10,11;""癸"",11,10,7,9,6,3,1,5,2,4,8,12}, FIND(REGEXREPLACE($H$7,""[^子丑寅卯辰巳午未申酉戌亥]"",""""), ""子丑寅卯辰巳午未申酉戌亥"")+1, FALSE), 0)"),9) -> 9 | BV20: =IFERROR(__xludf.DUMMYFUNCTION("IFERROR(VLOOKUP(""*""&AQ20&""*"", {""甲"",7,10,11,12,8,4,2,5,1,3,6,9;""乙"",4,8,12,11,10,7,9,6,3,1,5,2;""丙"",3,6,9,7,10,11,12,8,4,2,5,1;""丁"",1,5,2,4,8,12,11,10,7,9,6,3;""戊"",3,6,9,7,10,11,12,8,4,2,5,1;""己"",1,5,2,4,8,12,11,10,7,9,6,3;""庚"",2,5,1,3,6,9,7,10"&",11,12,8,4;""辛"",9,6,3,1,5,2,4,8,12,11,10,7;""壬"",12,8,4,2,5,1,3,6,9,7,10,11;""癸"",11,10,7,9,6,3,1,5,2,4,8,12}, FIND(REGEXREPLACE($G$7,""[^子丑寅卯辰巳午未申酉戌亥]"",""""), ""子丑寅卯辰巳午未申酉戌亥"")+1, FALSE), 0)"),7) -> 7 | BW20: =IFERROR(__xludf.DUMMYFUNCTION("IFERROR(VLOOKUP(""*""&AQ20&""*"", {""甲"",7,10,11,12,8,4,2,5,1,3,6,9;""乙"",4,8,12,11,10,7,9,6,3,1,5,2;""丙"",3,6,9,7,10,11,12,8,4,2,5,1;""丁"",1,5,2,4,8,12,11,10,7,9,6,3;""戊"",3,6,9,7,10,11,12,8,4,2,5,1;""己"",1,5,2,4,8,12,11,10,7,9,6,3;""庚"",2,5,1,3,6,9,7,10"&",11,12,8,4;""辛"",9,6,3,1,5,2,4,8,12,11,10,7;""壬"",12,8,4,2,5,1,3,6,9,7,10,11;""癸"",11,10,7,9,6,3,1,5,2,4,8,12}, FIND(REGEXREPLACE($F$7,""[^子丑寅卯辰巳午未申酉戌亥]"",""""), ""子丑寅卯辰巳午未申酉戌亥"")+1, FALSE), 0)"),1) -> 1 | BX20: =BT20 * (BU20 + BV20 + BW20) -> 0 | BY20: 金 | BZ20: =SUM(BX23:BX24) -> 89 | CA20: =BZ20/$BZ$22*100 -> 55.279503 | CB20: =ROUND((BZ20 / MAX($BZ$17:$BZ$21)) * 10, 0) -> 10 | CC20: 力の欲求 | CD20: 達成・承認・競争・課題の打破 | CF20: 10
F21: =[1]大運!F10 -> 大５ | G21: =[1]大運!G10 -> 辛卯 | H21: =[1]大運!H10 -> 2031 | I21: =[1]大運!I10 -> 50 | J21: =[1]大運!J10 -> 調舒星 | K21: =[1]大運!K10 -> 天恍星 | L21: =[1]大運!L10 -> 刑 | M21: =[1]大運!M10 -> － | ... P21: =[1]大運!P10 -> 月干 | AE21: =RIGHT(AH21, 1) -> 寅 | AF21: =IF(OR($E$6=RIGHT(AM21,1),$E$7=RIGHT(AM21,1)),"殺",AG21-$I$3) -> 5 | AG21: =AG20+1 -> 1986 | AH21: =VLOOKUP(AM21,[1]大運!$B$31:$C$90,2,FALSE) -> 丙寅 | AI21: =VLOOKUP($F$5&"+"&AM21,[1]大運!$H$45:$K$3644,3,FALSE) -> 龍高星 | AK21: =VLOOKUP($F$5&"+"&AM21,[1]大運!$H$45:$K$3644,4,FALSE) -> 天貴星 | AM21: =IF(MOD((AG21-1900+37),60)=0,60,MOD((AG21-1900+37),60)) -> 3 | AN21: =VLOOKUP($F$5&"+"&AM21,[1]大運!$H$45:$K$3644,2,FALSE) -> － | AO21: =VLOOKUP($G$5&"+"&AM21,[1]大運!$H$45:$K$3644,2,FALSE) -> 納音 | AP21: =VLOOKUP($H$5&"+"&AM21,[1]大運!$H$45:$K$3644,2,FALSE) -> － | AQ21: =IF(OR(RIGHT(AH22,1)=$E$6,RIGHT(AH22,1)=$E$7),"殺","")&IF(ABS(RIGHT(AM22,1)-RIGHT($F$5,1))=5,"日","")&IF(ABS(RIGHT(AM22,1)-RIGHT($G$5,1))=5,"月","")&IF(ABS(RIGHT(AM22,1)-RIGHT($H$5,1))=5,"年","") | AR21: =IF($AH21="","", IFERROR(IF(COUNTIF($F$6, MID("己庚辛壬癸甲乙丙丁戊", FIND(LEFT($AH21,1), "甲乙丙丁戊己庚辛壬癸"), 1))>0, CHOOSE(INT((FIND(LEFT($AH21,1), "甲己乙庚丙辛丁壬戊癸")+1)/2), "甲己干合", "乙庚干合", "丙辛干合", "丁壬干合", "戊癸干合"), ""), "")) | AS21: =IF($AH21="","", IFERROR(IF(COUNTIF($G$6, MID("己庚辛壬癸甲乙丙丁戊", FIND(LEFT($AH21,1), "甲乙丙丁戊己庚辛壬癸"), 1))>0, CHOOSE(INT((FIND(LEFT($AH21,1), "甲己乙庚丙辛丁壬戊癸")+1)/2), "甲己干合", "乙庚干合", "丙辛干合", "丁壬干合", "戊癸干合"), ""), "")) | AT21: =IF($AH21="","", IFERROR(IF(COUNTIF($H$6, MID("己庚辛壬癸甲乙丙丁戊", FIND(LEFT($AH21,1), "甲乙丙丁戊己庚辛壬癸"), 1))>0, CHOOSE(INT((FIND(LEFT($AH21,1), "甲己乙庚丙辛丁壬戊癸")+1)/2), "甲己干合", "乙庚干合", "丙辛干合", "丁壬干合", "戊癸干合"), ""), "")) -> 丙辛干合 | AU21: =INDEX('12運シート'!C:C, MATCH(1, INDEX(('12運シート'!A:A=TRIM($T$42)) * ('12運シート'!B:B=TRIM(RIGHT(AE21, 1))), 0), 0)) -> 乱気 | AV21: =INDEX('12運シート'!$E:$E, MATCH(1, INDEX((TRIM('12運シート'!$A:$A)=TRIM($T$42)) * (TRIM('12運シート'!$B:$B)=TRIM(AE21)), 0), 0)) -> 伏魔天 | AW21: =VLOOKUP(AV21,$V$6:$W$18, 2, FALSE) -> 強すぎる運気の反動で迷いや摩擦が生じる。理性と現状維持が必要な嵐。 | AZ21: =RIGHT(BC21, 1) -> 卯 | BA21: =BA20+1 -> 46147 | BB21: =MOD(BA21 - DATE(2024, 1, 1), 60) + 1 -> 16 | BC21: =VLOOKUP(BB21,[1]大運!$B$31:$C$90,2,FALSE) -> 己卯 | BD21: =VLOOKUP($F$5 & "+" & (MOD(BA21 - DATE(2024, 1, 1), 60) + 1), [1]大運!$H$45:$K$3644, 3, FALSE) -> 石門星 | BE21: =VLOOKUP($F$5 & "+" & (MOD(BA21 - DATE(2024, 1, 1), 60) + 1), [1]大運!$H$45:$K$3644, 4, FALSE) -> 天恍星 | BF21: =VLOOKUP($F$5 & "+" & (MOD(BA21 - DATE(2024, 1, 1), 60) + 1), [1]大運!$H$45:$K$3644, 2, FALSE) -> 刑 | BG21: =VLOOKUP($G$5 & "+" & (MOD(BA21 - DATE(2024, 1, 1), 60) + 1), [1]大運!$H$45:$K$3644, 2, FALSE) -> － | BH21: =VLOOKUP($H$5 & "+" & (MOD(BA21 - DATE(2024, 1, 1), 60) + 1), [1]大運!$H$45:$K$3644, 2, FALSE) -> 対冲 | BI21: =IF($BC21="","", IFERROR(IF(COUNTIF($F$6, MID("己庚辛壬癸甲乙丙丁戊", FIND(LEFT($BC21,1), "甲乙丙丁戊己庚辛壬癸"), 1))>0, CHOOSE(INT((FIND(LEFT($BC21,1), "甲己乙庚丙辛丁壬戊癸")+1)/2), "甲己干合", "乙庚干合", "丙辛干合", "丁壬干合", "戊癸干合"), ""), "")) | BJ21: =IF($BC21="","", IFERROR(IF(COUNTIF($G$6, MID("己庚辛壬癸甲乙丙丁戊", FIND(LEFT($BC21,1), "甲乙丙丁戊己庚辛壬癸"), 1))>0, CHOOSE(INT((FIND(LEFT($BC21,1), "甲己乙庚丙辛丁壬戊癸")+1)/2), "甲己干合", "乙庚干合", "丙辛干合", "丁壬干合", "戊癸干合"), ""), "")) | BK21: =IF($BC21="","", IFERROR(IF(COUNTIF($H$6, MID("己庚辛壬癸甲乙丙丁戊", FIND(LEFT($BC21,1), "甲乙丙丁戊己庚辛壬癸"), 1))>0, CHOOSE(INT((FIND(LEFT($BC21,1), "甲己乙庚丙辛丁壬戊癸")+1)/2), "甲己干合", "乙庚干合", "丙辛干合", "丁壬干合", "戊癸干合"), ""), "")) | BL21: =INDEX('12運シート'!C:C, MATCH(1, INDEX(('12運シート'!A:A=TRIM($T$42)) * ('12運シート'!B:B=TRIM(RIGHT(AZ21, 1))), 0), 0)) -> 再会 | BM21: =INDEX('12運シート'!$E:$E, MATCH(1, INDEX((TRIM('12運シート'!$A:$A)=TRIM($T$42)) * (TRIM('12運シート'!$B:$B)=TRIM(AZ21)), 0), 0)) -> 有頂天 | BN21: =VLOOKUP(BM21,$V$6:$W$18, 2, FALSE) -> 第2の絶頂期。過去の縁が繋がり、周囲を巻き込み大きな成果を出す。 | BQ21: 戊 | BT21: =COUNTIF($F$6:$H$10, "*"&BQ21&"*") -> 2 | BU21: =IFERROR(__xludf.DUMMYFUNCTION("IFERROR(VLOOKUP(""*""&AQ21&""*"", {""甲"",7,10,11,12,8,4,2,5,1,3,6,9;""乙"",4,8,12,11,10,7,9,6,3,1,5,2;""丙"",3,6,9,7,10,11,12,8,4,2,5,1;""丁"",1,5,2,4,8,12,11,10,7,9,6,3;""戊"",3,6,9,7,10,11,12,8,4,2,5,1;""己"",1,5,2,4,8,12,11,10,7,9,6,3;""庚"",2,5,1,3,6,9,7,10"&",11,12,8,4;""辛"",9,6,3,1,5,2,4,8,12,11,10,7;""壬"",12,8,4,2,5,1,3,6,9,7,10,11;""癸"",11,10,7,9,6,3,1,5,2,4,8,12}, FIND(REGEXREPLACE($H$7,""[^子丑寅卯辰巳午未申酉戌亥]"",""""), ""子丑寅卯辰巳午未申酉戌亥"")+1, FALSE), 0)"),2) -> 2 | BV21: =IFERROR(__xludf.DUMMYFUNCTION("IFERROR(VLOOKUP(""*""&AQ21&""*"", {""甲"",7,10,11,12,8,4,2,5,1,3,6,9;""乙"",4,8,12,11,10,7,9,6,3,1,5,2;""丙"",3,6,9,7,10,11,12,8,4,2,5,1;""丁"",1,5,2,4,8,12,11,10,7,9,6,3;""戊"",3,6,9,7,10,11,12,8,4,2,5,1;""己"",1,5,2,4,8,12,11,10,7,9,6,3;""庚"",2,5,1,3,6,9,7,10"&",11,12,8,4;""辛"",9,6,3,1,5,2,4,8,12,11,10,7;""壬"",12,8,4,2,5,1,3,6,9,7,10,11;""癸"",11,10,7,9,6,3,1,5,2,4,8,12}, FIND(REGEXREPLACE($G$7,""[^子丑寅卯辰巳午未申酉戌亥]"",""""), ""子丑寅卯辰巳午未申酉戌亥"")+1, FALSE), 0)"),4) -> 4 | BW21: =IFERROR(__xludf.DUMMYFUNCTION("IFERROR(VLOOKUP(""*""&AQ21&""*"", {""甲"",7,10,11,12,8,4,2,5,1,3,6,9;""乙"",4,8,12,11,10,7,9,6,3,1,5,2;""丙"",3,6,9,7,10,11,12,8,4,2,5,1;""丁"",1,5,2,4,8,12,11,10,7,9,6,3;""戊"",3,6,9,7,10,11,12,8,4,2,5,1;""己"",1,5,2,4,8,12,11,10,7,9,6,3;""庚"",2,5,1,3,6,9,7,10"&",11,12,8,4;""辛"",9,6,3,1,5,2,4,8,12,11,10,7;""壬"",12,8,4,2,5,1,3,6,9,7,10,11;""癸"",11,10,7,9,6,3,1,5,2,4,8,12}, FIND(REGEXREPLACE($F$7,""[^子丑寅卯辰巳午未申酉戌亥]"",""""), ""子丑寅卯辰巳午未申酉戌亥"")+1, FALSE), 0)"),3) -> 3 | BX21: =BT21 * (BU21 + BV21 + BW21) -> 18 | BY21: 水 | BZ21: =SUM(BX25:BX26) -> 45 | CA21: =BZ21/$BZ$22*100 -> 27.950311 | CB21: =ROUND((BZ21 / MAX($BZ$17:$BZ$21)) * 10, 0) -> 5 | CC21: 自由の欲求 | CD21: 独創性・独立・物理的／精神的制約の解放 | CF21: 11
